Workbook
Name LatestYear: 2020
Name nCol: COUNTA('Mack_Metodo 2'!$C$4:$N$4)-1
Name nRow: COUNTA('Mack_Metodo 2'!$B$5:$B$16)

Sheet Mack_Metodo1
T1: AY | U1: Diagonal | V1: Ultimate | W1: Claim Reserve | X1: Process Error | Y1: Process CV | Z1: Estim. Error | AA1: Estim. CV | AB1: Estim. Covariance Component | AC1: Total Error | AD1: CV (%)
E2: Cumulative paid claim amount | Z2: (without Dependence)
C3: DY | T3: 0 | U3: =N5 -> 86842.701 | V3: =N43 -> 86842.701 | W3: =V3-U3 -> 0 | X3: 0 | Y3: =IFERROR(X3/W3,"") | Z3: 0 | AA3: =IFERROR(Z3/W3,"") | AB3: 0 | AC3: =SUMSQ(X3,Z3)^0.5 -> 0 | AD3: =IFERROR(AC3/W3, "")
B4: i/j | C4: 0 | D4: 1 | E4: 2 | F4: 3 | G4: 4 | H4: 5 | I4: 6 | J4: 7 | K4: 8 | L4: 9 | M4: 10 | N4: 11 | T4: =T3+1 -> 1 | U4: =M6 -> 96325.022 | V4: =N44 -> 98358.305 | W4: =V4-U4 -> 2033.2831 | X4: =(V4^2*O79)^0.5 -> 32.220985 | Y4: =IFERROR(X4/W4,"") -> 0.015846778 | Z4: =(V4^2*HLOOKUP(11-T4,$C$92:$M$94,3,FALSE))^0.5 -> 34.290804 | AA4: =IFERROR(Z4/W4,"") -> 0.016864747 | AB4: =IF(T4<11,HLOOKUP(11-T4,$C$92:$M$94,3,FALSE)*V4*SUM(V5:$V$14),0) -> 16747.22 | AC4: =SUMSQ(X4,Z4)^0.5 -> 47.053705 | AD4: =IFERROR(AC4/W4, "") -> 0.023141738
B5: 0 | C5: 28446.238 | D5: 57697.432 | E5: 70161.415 | F5: 75305.501 | G5: 78032.449 | H5: 80391.811 | I5: 81725.667 | J5: 82964.097 | K5: 83905.538 | L5: 84765.601 | M5: 85047.471 | N5: 86842.701 | T5: =T4+1 -> 2 | U5: =L7 -> 105007.48 | V5: =N45 -> 107662.2 | W5: =V5-U5 -> 2654.7155 | X5: =(V5^2*O80)^0.5 -> 106.14053 | Y5: =IFERROR(X5/W5,"") -> 0.039981887 | Z5: =(V5^2*HLOOKUP(11-T5,$C$92:$M$94,3,FALSE))^0.5 -> 85.424406 | AA5: =IFERROR(Z5/W5,"") -> 0.032178366 | AB5: =IF(T5<11,HLOOKUP(11-T5,$C$92:$M$94,3,FALSE)*V5*SUM(V6:$V$14),0) -> 87653.572 | AC5: =SUMSQ(X5,Z5)^0.5 -> 136.24662 | AD5: =IFERROR(AC5/W5, "") -> 0.051322495
B6: =B5+1 -> 1 | C6: 31963.048 | D6: 68069.343 | E6: 81510.677 | F6: 87378.911 | G6: 90260.884 | H6: 92682.871 | I6: 93600.876 | J6: 94676.854 | K6: 95410.595 | L6: 95868.751 | M6: 96325.022 | T6: =T5+1 -> 3 | U6: =K8 -> 114674.41 | V6: =N46 -> 118351.46 | W6: =V6-U6 -> 3677.0462 | X6: =(V6^2*O81)^0.5 -> 328.80966 | Y6: =IFERROR(X6/W6,"") -> 0.089422227 | Z6: =(V6^2*HLOOKUP(11-T6,$C$92:$M$94,3,FALSE))^0.5 -> 217.95677 | AA6: =IFERROR(Z6/W6,"") -> 0.059274961 | AB6: =IF(T6<11,HLOOKUP(11-T6,$C$92:$M$94,3,FALSE)*V6*SUM(V7:$V$14),0) -> 471576.93 | AC6: =SUMSQ(X6,Z6)^0.5 -> 394.48821 | AD6: =IFERROR(AC6/W6, "") -> 0.107284
B7: =B6+1 -> 2 | C7: 37774.74 | D7: 77900.131 | E7: 90851.307 | F7: 96885.063 | G7: 99894.719 | H7: 101159.11 | I7: 102409.07 | J7: 103543.77 | K7: 104448.14 | L7: 105007.48 | T7: =T6+1 -> 4 | U7: =J9 -> 118289.46 | V7: =N47 -> 123149.43 | W7: =V7-U7 -> 4859.9647 | X7: =(V7^2*O82)^0.5 -> 381.55064 | Y7: =IFERROR(X7/W7,"") -> 0.078508933 | Z7: =(V7^2*HLOOKUP(11-T7,$C$92:$M$94,3,FALSE))^0.5 -> 247.67373 | AA7: =IFERROR(Z7/W7,"") -> 0.050962043 | AB7: =IF(T7<11,HLOOKUP(11-T7,$C$92:$M$94,3,FALSE)*V7*SUM(V8:$V$14),0) -> 523869.34 | AC7: =SUMSQ(X7,Z7)^0.5 -> 454.88808 | AD7: =IFERROR(AC7/W7, "") -> 0.093599052
B8: =B7+1 -> 3 | C8: 40417.572 | D8: 84916.514 | E8: 100286.94 | F8: 105880.79 | G8: 108496.31 | H8: 110480.62 | I8: 112617.42 | J8: 113801.78 | K8: 114674.41 | T8: =T7+1 -> 5 | U8: =I10 -> 132138.57 | V8: =N48 -> 139128.24 | W8: =V8-U8 -> 6989.6674 | X8: =(V8^2*O83)^0.5 -> 472.0633 | Y8: =IFERROR(X8/W8,"") -> 0.067537305 | Z8: =(V8^2*HLOOKUP(11-T8,$C$92:$M$94,3,FALSE))^0.5 -> 305.76422 | AA8: =IFERROR(Z8/W8,"") -> 0.043745175 | AB8: =IF(T8<11,HLOOKUP(11-T8,$C$92:$M$94,3,FALSE)*V8*SUM(V9:$V$14),0) -> 613238.25 | AC8: =SUMSQ(X8,Z8)^0.5 -> 562.43712 | AD8: =IFERROR(AC8/W8, "") -> 0.080466936
B9: =B8+1 -> 4 | C9: 44116.086 | D9: 89606.275 | E9: 104945.7 | F9: 110423.78 | G9: 112964.42 | H9: 115870.79 | I9: 117165.12 | J9: 118289.46 | T9: =T8+1 -> 6 | U9: =H11 -> 138291.01 | V9: =N49 -> 147730.79 | W9: =V9-U9 -> 9439.7771 | X9: =(V9^2*O84)^0.5 -> 689.19771 | Y9: =IFERROR(X9/W9,"") -> 0.073009956 | Z9: =(V9^2*HLOOKUP(11-T9,$C$92:$M$94,3,FALSE))^0.5 -> 397.11141 | AA9: =IFERROR(Z9/W9,"") -> 0.042067879 | AB9: =IF(T9<11,HLOOKUP(11-T9,$C$92:$M$94,3,FALSE)*V9*SUM(V10:$V$14),0) -> 816450.42 | AC9: =SUMSQ(X9,Z9)^0.5 -> 795.41872 | AD9: =IFERROR(AC9/W9, "") -> 0.084262448
B10: =B9+1 -> 5 | C10: 50294.26 | D10: 98334.581 | E10: 116177.48 | F10: 123212.68 | G10: 127146.29 | H10: 129871.97 | I10: 132138.57 | T10: =T9+1 -> 7 | U10: =G12 -> 129900.41 | V10: =N50 -> 141900.77 | W10: =V10-U10 -> 12000.357 | X10: =(V10^2*O85)^0.5 -> 972.9057 | Y10: =IFERROR(X10/W10,"") -> 0.081073064 | Z10: =(V10^2*HLOOKUP(11-T10,$C$92:$M$94,3,FALSE))^0.5 -> 479.80806 | AA10: =IFERROR(Z10/W10,"") -> 0.039982816 | AB10: =IF(T10<11,HLOOKUP(11-T10,$C$92:$M$94,3,FALSE)*V10*SUM(V11:$V$14),0) -> 1010654.7 | AC10: =SUMSQ(X10,Z10)^0.5 -> 1084.7863 | AD10: =IFERROR(AC10/W10, "") -> 0.090396169
B11: =B10+1 -> 6 | C11: 49619.804 | D11: 99611.162 | E11: 119181.37 | F11: 129228.43 | G11: 134978.32 | H11: 138291.01 | T11: =T10+1 -> 8 | U11: =F13 -> 124786.08 | V11: =N51 -> 140813.43 | W11: =V11-U11 -> 16027.344 | X11: =(V11^2*O86)^0.5 -> 1333.0766 | Y11: =IFERROR(X11/W11,"") -> 0.083175142 | Z11: =(V11^2*HLOOKUP(11-T11,$C$92:$M$94,3,FALSE))^0.5 -> 590.92447 | AA11: =IFERROR(Z11/W11,"") -> 0.036869769 | AB11: =IF(T11<11,HLOOKUP(11-T11,$C$92:$M$94,3,FALSE)*V11*SUM(V12:$V$14),0) -> 1195608.6 | AC11: =SUMSQ(X11,Z11)^0.5 -> 1458.1786 | AD11: =IFERROR(AC11/W11, "") -> 0.09098068
B12: =B11+1 -> 7 | C12: 46409.721 | D12: 96104.016 | E12: 116984.68 | F12: 125186.24 | G12: 129900.41 | T12: =T11+1 -> 9 | U12: =E14 -> 121799.75 | V12: =N52 -> 146781.26 | W12: =V12-U12 -> 24981.508 | X12: =(V12^2*O87)^0.5 -> 1902.1444 | Y12: =IFERROR(X12/W12,"") -> 0.076142094 | Z12: =(V12^2*HLOOKUP(11-T12,$C$92:$M$94,3,FALSE))^0.5 -> 783.70495 | AA12: =IFERROR(Z12/W12,"") -> 0.031371402 | AB12: =IF(T12<11,HLOOKUP(11-T12,$C$92:$M$94,3,FALSE)*V12*SUM(V13:$V$14),0) -> 1403260.9 | AC12: =SUMSQ(X12,Z12)^0.5 -> 2057.2668 | AD12: =IFERROR(AC12/W12, "") -> 0.082351584
B13: =B12+1 -> 8 | C13: 48294.758 | D13: 97648.347 | E13: 115952.59 | F13: 124786.08 | T13: =T12+1 -> 10 | U13: =D15 -> 112342 | V13: =N53 -> 160933.26 | W13: =V13-U13 -> 48591.257 | X13: =(V13^2*O88)^0.5 -> 2811.3668 | Y13: =IFERROR(X13/W13,"") -> 0.057857461 | Z13: =(V13^2*HLOOKUP(11-T13,$C$92:$M$94,3,FALSE))^0.5 -> 1115.7486 | AA13: =IFERROR(Z13/W13,"") -> 0.022961921 | AB13: =IF(T13<11,HLOOKUP(11-T13,$C$92:$M$94,3,FALSE)*V13*SUM(V14:$V$14),0) -> 1349229.1 | AC13: =SUMSQ(X13,Z13)^0.5 -> 3024.6782 | AD13: =IFERROR(AC13/W13, "") -> 0.062247375
B14: =B13+1 -> 9 | C14: 52590.22 | D14: 103196.04 | E14: 121799.75 | T14: =T13+1 -> 11 | U14: =C16 -> 60361.276 | V14: =N54 -> 174421.02 | W14: =V14-U14 -> 114059.74 | X14: =(V14^2*O89)^0.5 -> 5615.576 | Y14: =IFERROR(X14/W14,"") -> 0.049233637 | Z14: =(V14^2*HLOOKUP(11-T14,$C$92:$M$94,3,FALSE))^0.5 -> 2073.7048 | AA14: =IFERROR(Z14/W14,"") -> 0.018180865 | AB14: =IF(T14<11,HLOOKUP(11-T14,$C$92:$M$94,3,FALSE)*V14*SUM(V$14:$V15),0) -> 0 | AC14: =SUMSQ(X14,Z14)^0.5 -> 5986.2296 | AD14: =IFERROR(AC14/W14, "") -> 0.052483282
B15: =B14+1 -> 10 | C15: 58599 | D15: 112342
B16: =B15+1 -> 11 | C16: 60361.276 | T16: Total | U16: =SUM(U3:U14) -> 1340758.2 | V16: =SUM(V3:V14) -> 1586072.9 | W16: =SUM(W3:W14) -> 245314.66 | X16: =+SUMSQ(X3:X14)^0.5 -> 6836.9662 | Y16: =X16/W16 -> 0.02787019 | Z16: =+SUMSQ(Z3:Z14)^0.5 -> 2665.9439 | AA16: =Z16/W16 -> 0.010867446 | AB16: Independence | AC16: =SQRT(X16^2+Z16^2) -> 7338.3489 | AD16: =AC16/W16 -> 0.029914025
Y17: With dependence | Z17: =SQRT(Z16^2+AB17*2) -> 4699.3441 | AA17: =Z17/W16 -> 0.019156393 | AB17: =SUM(AB3:AB14) -> 7488289 | AC17: =(Z16^2+X16^2+2*AB17)^0.5 -> 8296.2607 | AD17: =AC17/W16 -> 0.033818854
AB18: Full Correlation EV | AC18: =(X16^2+SUM(Z4:Z14)^2)^0.5 -> 9318.7849 | AD18: =AC18/W16 -> 0.037987068
AB19: Full Correlation Total | AC19: =SQRT(SUM(X4:X14)^2+SUM(Z4:Z14)^2) -> 15955.35 | AD19: =AC19/W16 -> 0.065040345
E21: Link ratios (a.k.a. age-to-age factors)
C22: DY
B23: i/j | C23: 0 | D23: 1 | E23: 2 | F23: 3 | G23: 4 | H23: 5 | I23: 6 | J23: 7 | K23: 8 | L23: 9 | M23: 10 | N23: 11
B24: 0 | C24: =D5/C5 -> 2.0282974 | D24: =E5/D5 -> 1.2160232 | E24: =F5/E5 -> 1.0733179 | F24: =G5/F5 -> 1.0362118 | G24: =H5/G5 -> 1.0302357 | H24: =I5/H5 -> 1.0165919 | I24: =J5/I5 -> 1.0151535 | J24: =K5/J5 -> 1.0113476 | ... M24: =N5/M5 -> 1.0211086
B25: =B24+1 -> 1 | C25: =D6/C6 -> 2.1296262 | D25: =E6/D6 -> 1.1974653 | E25: =F6/E6 -> 1.0719934 | F25: =G6/F6 -> 1.0329825 | G25: =H6/G6 -> 1.0268332 | H25: =I6/H6 -> 1.0099048 | I25: =J6/I6 -> 1.0114954 | J25: =K6/J6 -> 1.00775 | ... L25: =M6/L6 -> 1.0047593 | M25: =IFERROR(IF(N6<>"",IF($B25+M$23 <= LatestYear,N6/M6,""),""),"") | N25: =IFERROR(IF(#REF!<>"",IF($B25+N$23 <= LatestYear,#REF!/N6,""),""),"")
B26: =B25+1 -> 2 | C26: =D7/C7 -> 2.0622281 | D26: =E7/D7 -> 1.1662536 | E26: =F7/E7 -> 1.0664135 | F26: =G7/F7 -> 1.0310642 | G26: =H7/G7 -> 1.0126573 | H26: =I7/H7 -> 1.0123563 | I26: =J7/I7 -> 1.0110801 | J26: =K7/J7 -> 1.0087342 | K26: =L7/K7 -> 1.0053552 | L26: =IFERROR(IF(M7<>"",IF($B26+L$23 <= LatestYear,M7/L7,""),""),"") | M26: =IFERROR(IF(N7<>"",IF($B26+M$23 <= LatestYear,N7/M7,""),""),"") | N26: =IFERROR(IF(#REF!<>"",IF($B26+N$23 <= LatestYear,#REF!/N7,""),""),"")
B27: =B26+1 -> 3 | C27: =D8/C8 -> 2.1009801 | D27: =E8/D8 -> 1.1810063 | E27: =F8/E8 -> 1.0557785 | F27: =G8/F8 -> 1.0247025 | G27: =H8/G8 -> 1.0182892 | H27: =I8/H8 -> 1.019341 | I27: =J8/I8 -> 1.0105166 | J27: =K8/J8 -> 1.007668 | K27: =IFERROR(IF(L8<>"",IF($B27+K$23 <= LatestYear,L8/K8,""),""),"") | L27: =IFERROR(IF(M8<>"",IF($B27+L$23 <= LatestYear,M8/L8,""),""),"") | M27: =IFERROR(IF(N8<>"",IF($B27+M$23 <= LatestYear,N8/M8,""),""),"") | N27: =IFERROR(IF(#REF!<>"",IF($B27+N$23 <= LatestYear,#REF!/N8,""),""),"")
B28: =B27+1 -> 4 | C28: =D9/C9 -> 2.0311475 | D28: =E9/D9 -> 1.171187 | E28: =F9/E9 -> 1.0521992 | F28: =G9/F9 -> 1.0230081 | G28: =H9/G9 -> 1.0257282 | H28: =I9/H9 -> 1.0111705 | I28: =J9/I9 -> 1.0095962 | J28: =IFERROR(IF(K9<>"",IF($B28+J$23 <= LatestYear,K9/J9,""),""),"") | K28: =IFERROR(IF(L9<>"",IF($B28+K$23 <= LatestYear,L9/K9,""),""),"") | L28: =IFERROR(IF(M9<>"",IF($B28+L$23 <= LatestYear,M9/L9,""),""),"") | M28: =IFERROR(IF(N9<>"",IF($B28+M$23 <= LatestYear,N9/M9,""),""),"") | N28: =IFERROR(IF(#REF!<>"",IF($B28+N$23 <= LatestYear,#REF!/N9,""),""),"")
B29: =B28+1 -> 5 | C29: =D10/C10 -> 1.955185 | D29: =E10/D10 -> 1.1814509 | E29: =F10/E10 -> 1.0605556 | F29: =G10/F10 -> 1.0319253 | G29: =H10/G10 -> 1.0214374 | H29: =I10/H10 -> 1.0174526 | I29: =IFERROR(IF(J10<>"",IF($B29+I$23 <= LatestYear,J10/I10,""),""),"") | J29: =IFERROR(IF(K10<>"",IF($B29+J$23 <= LatestYear,K10/J10,""),""),"") | K29: =IFERROR(IF(L10<>"",IF($B29+K$23 <= LatestYear,L10/K10,""),""),"") | L29: =IFERROR(IF(M10<>"",IF($B29+L$23 <= LatestYear,M10/L10,""),""),"") | M29: =IFERROR(IF(N10<>"",IF($B29+M$23 <= LatestYear,N10/M10,""),""),"") | N29: =IFERROR(IF(#REF!<>"",IF($B29+N$23 <= LatestYear,#REF!/N10,""),""),"")
B30: =B29+1 -> 6 | C30: =D11/C11 -> 2.007488 | D30: =E11/D11 -> 1.196466 | E30: =F11/E11 -> 1.0843007 | F30: =G11/F11 -> 1.044494 | G30: =H11/G11 -> 1.0245424 | H30: =IFERROR(IF(I11<>"",IF($B30+H$23 <= LatestYear,I11/H11,""),""),"") | I30: =IFERROR(IF(J11<>"",IF($B30+I$23 <= LatestYear,J11/I11,""),""),"") | J30: =IFERROR(IF(K11<>"",IF($B30+J$23 <= LatestYear,K11/J11,""),""),"") | K30: =IFERROR(IF(L11<>"",IF($B30+K$23 <= LatestYear,L11/K11,""),""),"") | L30: =IFERROR(IF(M11<>"",IF($B30+L$23 <= LatestYear,M11/L11,""),""),"") | M30: =IFERROR(IF(N11<>"",IF($B30+M$23 <= LatestYear,N11/M11,""),""),"") | N30: =IFERROR(IF(#REF!<>"",IF($B30+N$23 <= LatestYear,#REF!/N11,""),""),"")
B31: =B30+1 -> 7 | C31: =D12/C12 -> 2.0707734 | D31: =E12/D12 -> 1.2172715 | E31: =F12/E12 -> 1.070108 | F31: =G12/F12 -> 1.0376572 | G31: =IFERROR(IF(H12<>"",IF($B31+G$23 <= LatestYear,H12/G12,""),""),"") | H31: =IFERROR(IF(I12<>"",IF($B31+H$23 <= LatestYear,I12/H12,""),""),"") | I31: =IFERROR(IF(J12<>"",IF($B31+I$23 <= LatestYear,J12/I12,""),""),"") | J31: =IFERROR(IF(K12<>"",IF($B31+J$23 <= LatestYear,K12/J12,""),""),"") | K31: =IFERROR(IF(L12<>"",IF($B31+K$23 <= LatestYear,L12/K12,""),""),"") | L31: =IFERROR(IF(M12<>"",IF($B31+L$23 <= LatestYear,M12/L12,""),""),"") | M31: =IFERROR(IF(N12<>"",IF($B31+M$23 <= LatestYear,N12/M12,""),""),"") | N31: =IFERROR(IF(#REF!<>"",IF($B31+N$23 <= LatestYear,#REF!/N12,""),""),"")
B32: =B31+1 -> 8 | C32: =D13/C13 -> 2.0219244 | D32: =E13/D13 -> 1.1874506 | E32: =F13/E13 -> 1.0761819 | F32: =IFERROR(IF(G13<>"",IF($B32+F$23 <= LatestYear,G13/F13,""),""),"") | G32: =IFERROR(IF(H13<>"",IF($B32+G$23 <= LatestYear,H13/G13,""),""),"") | H32: =IFERROR(IF(I13<>"",IF($B32+H$23 <= LatestYear,I13/H13,""),""),"") | I32: =IFERROR(IF(J13<>"",IF($B32+I$23 <= LatestYear,J13/I13,""),""),"") | J32: =IFERROR(IF(K13<>"",IF($B32+J$23 <= LatestYear,K13/J13,""),""),"") | K32: =IFERROR(IF(L13<>"",IF($B32+K$23 <= LatestYear,L13/K13,""),""),"") | L32: =IFERROR(IF(M13<>"",IF($B32+L$23 <= LatestYear,M13/L13,""),""),"") | M32: =IFERROR(IF(N13<>"",IF($B32+M$23 <= LatestYear,N13/M13,""),""),"") | N32: =IFERROR(IF(#REF!<>"",IF($B32+N$23 <= LatestYear,#REF!/N13,""),""),"")
B33: =B32+1 -> 9 | C33: =D14/C14 -> 1.9622667 | D33: =E14/D14 -> 1.1802755 | E33: =IFERROR(IF(F14<>"",IF($B33+E$23 <= LatestYear,F14/E14,""),""),"") | F33: =IFERROR(IF(G14<>"",IF($B33+F$23 <= LatestYear,G14/F14,""),""),"") | G33: =IFERROR(IF(H14<>"",IF($B33+G$23 <= LatestYear,H14/G14,""),""),"") | H33: =IFERROR(IF(I14<>"",IF($B33+H$23 <= LatestYear,I14/H14,""),""),"") | I33: =IFERROR(IF(J14<>"",IF($B33+I$23 <= LatestYear,J14/I14,""),""),"") | J33: =IFERROR(IF(K14<>"",IF($B33+J$23 <= LatestYear,K14/J14,""),""),"") | K33: =IFERROR(IF(L14<>"",IF($B33+K$23 <= LatestYear,L14/K14,""),""),"") | L33: =IFERROR(IF(M14<>"",IF($B33+L$23 <= LatestYear,M14/L14,""),""),"") | M33: =IFERROR(IF(N14<>"",IF($B33+M$23 <= LatestYear,N14/M14,""),""),"") | N33: =IFERROR(IF(#REF!<>"",IF($B33+N$23 <= LatestYear,#REF!/N14,""),""),"")
B34: =B33+1 -> 10 | C34: =D15/C15 -> 1.9171317 | D34: =IFERROR(IF(E15<>"",IF($B34+D$23 <= LatestYear,E15/D15,""),""),"") | E34: =IFERROR(IF(F15<>"",IF($B34+E$23 <= LatestYear,F15/E15,""),""),"") | F34: =IFERROR(IF(G15<>"",IF($B34+F$23 <= LatestYear,G15/F15,""),""),"") | G34: =IFERROR(IF(H15<>"",IF($B34+G$23 <= LatestYear,H15/G15,""),""),"") | H34: =IFERROR(IF(I15<>"",IF($B34+H$23 <= LatestYear,I15/H15,""),""),"") | I34: =IFERROR(IF(J15<>"",IF($B34+I$23 <= LatestYear,J15/I15,""),""),"") | J34: =IFERROR(IF(K15<>"",IF($B34+J$23 <= LatestYear,K15/J15,""),""),"") | K34: =IFERROR(IF(L15<>"",IF($B34+K$23 <= LatestYear,L15/K15,""),""),"") | ... M34: =IFERROR(IF(N15<>"",IF($B34+M$23 <= LatestYear,N15/M15,""),""),"") | N34: =IFERROR(IF(#REF!<>"",IF($B34+N$23 <= LatestYear,#REF!/N15,""),""),"")
B35: =B34+1 -> 11 | C35: =IFERROR(IF(D16<>"",IF($B35+C$23 <= LatestYear,D16/C16,""),""),"") | D35: =IFERROR(IF(E16<>"",IF($B35+D$23 <= LatestYear,E16/D16,""),""),"") | E35: =IFERROR(IF(F16<>"",IF($B35+E$23 <= LatestYear,F16/E16,""),""),"") | F35: =IFERROR(IF(G16<>"",IF($B35+F$23 <= LatestYear,G16/F16,""),""),"") | G35: =IFERROR(IF(H16<>"",IF($B35+G$23 <= LatestYear,H16/G16,""),""),"") | H35: =IFERROR(IF(I16<>"",IF($B35+H$23 <= LatestYear,I16/H16,""),""),"") | I35: =IFERROR(IF(J16<>"",IF($B35+I$23 <= LatestYear,J16/I16,""),""),"") | J35: =IFERROR(IF(K16<>"",IF($B35+J$23 <= LatestYear,K16/J16,""),""),"") | ... M35: =IFERROR(IF(N16<>"",IF($B35+M$23 <= LatestYear,N16/M16,""),""),"") | N35: =IFERROR(IF(#REF!<>"",IF($B35+N$23 <= LatestYear,#REF!/N16,""),""),"")
B37: Development factors | C37: 0 | D37: 1 | E37: =D37+1 -> 2 | F37: =E37+1 -> 3 | G37: =F37+1 -> 4 | H37: =G37+1 -> 5 | I37: =H37+1 -> 6 | J37: =I37+1 -> 7 | K37: =J37+1 -> 8 | L37: =K37+1 -> 9 | M37: =L37+1 -> 10
B38: lambda | C38: =SUM(D5:D16)/(SUM(C5:C16)-VLOOKUP(11-C37,$B5:C16,C37+2,FALSE)) -> 2.0171433 | D38: =SUM(E5:E16)/(SUM(D5:D16)-VLOOKUP(11-D37,$B5:D16,D37+2,FALSE)) -> 1.1887196 | E38: =SUM(F5:F16)/(SUM(E5:E16)-VLOOKUP(11-E37,$B5:E16,E37+2,FALSE)) -> 1.0679386 | F38: =SUM(G5:G16)/(SUM(F5:F16)-VLOOKUP(11-F37,$B5:F16,F37+2,FALSE)) -> 1.033008 | G38: =SUM(H5:H16)/(SUM(G5:G16)-VLOOKUP(11-G37,$B5:G16,G37+2,FALSE)) -> 1.0225797 | H38: =SUM(I5:I16)/(SUM(H5:H16)-VLOOKUP(11-H37,$B5:H16,H37+2,FALSE)) -> 1.0145919 | I38: =SUM(J5:J16)/(SUM(I5:I16)-VLOOKUP(11-I37,$B5:I16,I37+2,FALSE)) -> 1.011345 | J38: =SUM(K5:K16)/(SUM(J5:J16)-VLOOKUP(11-J37,$B5:J16,J37+2,FALSE)) -> 1.00874 | ... M38: =SUM(N5:N16)/(SUM(M5:M16)-VLOOKUP(11-M37,$B5:M16,M37+2,FALSE)) -> 1.0211086
B39: CDF | C39: =PRODUCT(C$38:$M$38) -> 2.8896178 | D39: =PRODUCT(D$38:$M$38) -> 1.4325297 | E39: =PRODUCT(E$38:$M$38) -> 1.2051031 | F39: =PRODUCT(F$38:$M$38) -> 1.1284386 | G39: =PRODUCT(G$38:$M$38) -> 1.0923812 | H39: =PRODUCT(H$38:$M$38) -> 1.0682602 | I39: =PRODUCT(I$38:$M$38) -> 1.0528965 | J39: =PRODUCT(J$38:$M$38) -> 1.0410854 | ... M39: =PRODUCT(M$38:$M$38) -> 1.0211086
B41: Cumulative Amounts
B42: i/j | C42: 0 | D42: 1 | E42: =D42+1 -> 2 | F42: =E42+1 -> 3 | G42: =F42+1 -> 4 | H42: =G42+1 -> 5 | I42: =H42+1 -> 6 | J42: =I42+1 -> 7 | K42: =J42+1 -> 8 | L42: =K42+1 -> 9 | M42: =L42+1 -> 10 | N42: 11
B43: 0 | C43: =C5 -> 28446.238 | D43: =D5 -> 57697.432 | E43: =E5 -> 70161.415 | F43: =F5 -> 75305.501 | G43: =G5 -> 78032.449 | H43: =H5 -> 80391.811 | I43: =I5 -> 81725.667 | J43: =J5 -> 82964.097 | ... N43: =N5 -> 86842.701
...

Sheet Mack_Metodo 2
E2: Cumulative paid claim amount
C3: DY
B4: AY | C4: 0 | D4: 1 | E4: 2 | F4: 3 | G4: 4 | H4: 5 | I4: 6 | J4: 7 | K4: 8 | L4: 9 | M4: 10 | N4: 11
B5: 2009 | C5: =Mack_Metodo1!C5 -> 28446.238 | D5: =Mack_Metodo1!D5 -> 57697.432 | E5: =Mack_Metodo1!E5 -> 70161.415 | F5: =Mack_Metodo1!F5 -> 75305.501 | G5: =Mack_Metodo1!G5 -> 78032.449 | H5: =Mack_Metodo1!H5 -> 80391.811 | I5: =Mack_Metodo1!I5 -> 81725.667 | J5: =Mack_Metodo1!J5 -> 82964.097 | ... N5: =Mack_Metodo1!N5 -> 86842.701
B6: 2010 | C6: =Mack_Metodo1!C6 -> 31963.048 | D6: =Mack_Metodo1!D6 -> 68069.343 | E6: =Mack_Metodo1!E6 -> 81510.677 | F6: =Mack_Metodo1!F6 -> 87378.911 | G6: =Mack_Metodo1!G6 -> 90260.884 | H6: =Mack_Metodo1!H6 -> 92682.871 | I6: =Mack_Metodo1!I6 -> 93600.876 | J6: =Mack_Metodo1!J6 -> 94676.854 | ... M6: =Mack_Metodo1!M6 -> 96325.022
B7: 2011 | C7: =Mack_Metodo1!C7 -> 37774.74 | D7: =Mack_Metodo1!D7 -> 77900.131 | E7: =Mack_Metodo1!E7 -> 90851.307 | F7: =Mack_Metodo1!F7 -> 96885.063 | G7: =Mack_Metodo1!G7 -> 99894.719 | H7: =Mack_Metodo1!H7 -> 101159.11 | I7: =Mack_Metodo1!I7 -> 102409.07 | J7: =Mack_Metodo1!J7 -> 103543.77 | ... L7: =Mack_Metodo1!L7 -> 105007.48
B8: 2012 | C8: =Mack_Metodo1!C8 -> 40417.572 | D8: =Mack_Metodo1!D8 -> 84916.514 | E8: =Mack_Metodo1!E8 -> 100286.94 | F8: =Mack_Metodo1!F8 -> 105880.79 | G8: =Mack_Metodo1!G8 -> 108496.31 | H8: =Mack_Metodo1!H8 -> 110480.62 | I8: =Mack_Metodo1!I8 -> 112617.42 | J8: =Mack_Metodo1!J8 -> 113801.78 | K8: =Mack_Metodo1!K8 -> 114674.41
B9: 2013 | C9: =Mack_Metodo1!C9 -> 44116.086 | D9: =Mack_Metodo1!D9 -> 89606.275 | E9: =Mack_Metodo1!E9 -> 104945.7 | F9: =Mack_Metodo1!F9 -> 110423.78 | G9: =Mack_Metodo1!G9 -> 112964.42 | H9: =Mack_Metodo1!H9 -> 115870.79 | I9: =Mack_Metodo1!I9 -> 117165.12 | J9: =Mack_Metodo1!J9 -> 118289.46
B10: 2014 | C10: =Mack_Metodo1!C10 -> 50294.26 | D10: =Mack_Metodo1!D10 -> 98334.581 | E10: =Mack_Metodo1!E10 -> 116177.48 | F10: =Mack_Metodo1!F10 -> 123212.68 | G10: =Mack_Metodo1!G10 -> 127146.29 | H10: =Mack_Metodo1!H10 -> 129871.97 | I10: =Mack_Metodo1!I10 -> 132138.57
B11: 2015 | C11: =Mack_Metodo1!C11 -> 49619.804 | D11: =Mack_Metodo1!D11 -> 99611.162 | E11: =Mack_Metodo1!E11 -> 119181.37 | F11: =Mack_Metodo1!F11 -> 129228.43 | G11: =Mack_Metodo1!G11 -> 134978.32 | H11: =Mack_Metodo1!H11 -> 138291.01
B12: 2016 | C12: =Mack_Metodo1!C12 -> 46409.721 | D12: =Mack_Metodo1!D12 -> 96104.016 | E12: =Mack_Metodo1!E12 -> 116984.68 | F12: =Mack_Metodo1!F12 -> 125186.24 | G12: =Mack_Metodo1!G12 -> 129900.41
B13: 2017 | C13: =Mack_Metodo1!C13 -> 48294.758 | D13: =Mack_Metodo1!D13 -> 97648.347 | E13: =Mack_Metodo1!E13 -> 115952.59 | F13: =Mack_Metodo1!F13 -> 124786.08
B14: 2018 | C14: =Mack_Metodo1!C14 -> 52590.22 | D14: =Mack_Metodo1!D14 -> 103196.04 | E14: =Mack_Metodo1!E14 -> 121799.75
B15: 2019 | C15: =Mack_Metodo1!C15 -> 58599 | D15: =Mack_Metodo1!D15 -> 112342
B16: 2020 | C16: =Mack_Metodo1!C16 -> 60361.276
E21: Link ratios (a.k.a. age-to-age factors)
C22: DY
B23: AY | C23: 0 | D23: 1 | E23: 2 | F23: 3 | G23: 4 | H23: 5 | I23: 6 | J23: 7 | K23: 8 | L23: 9 | M23: 10 | N23: 11
B24: 2009 | C24: =IFERROR(IF(D5<>"",IF($B24+C$23 <= LatestYear,D5/C5,""),""),"") -> 2.0282974 | D24: =IFERROR(IF(E5<>"",IF($B24+D$23 <= LatestYear,E5/D5,""),""),"") -> 1.2160232 | E24: =IFERROR(IF(F5<>"",IF($B24+E$23 <= LatestYear,F5/E5,""),""),"") -> 1.0733179 | F24: =IFERROR(IF(G5<>"",IF($B24+F$23 <= LatestYear,G5/F5,""),""),"") -> 1.0362118 | G24: =IFERROR(IF(H5<>"",IF($B24+G$23 <= LatestYear,H5/G5,""),""),"") -> 1.0302357 | H24: =IFERROR(IF(I5<>"",IF($B24+H$23 <= LatestYear,I5/H5,""),""),"") -> 1.0165919 | I24: =IFERROR(IF(J5<>"",IF($B24+I$23 <= LatestYear,J5/I5,""),""),"") -> 1.0151535 | J24: =IFERROR(IF(K5<>"",IF($B24+J$23 <= LatestYear,K5/J5,""),""),"") -> 1.0113476 | ... N24: =IFERROR(IF(O5<>"",IF($B24+N$23 <= LatestYear,O5/N5,""),""),"")
B25: 2010 | C25: =IFERROR(IF(D6<>"",IF($B25+C$23 <= LatestYear,D6/C6,""),""),"") -> 2.1296262 | D25: =IFERROR(IF(E6<>"",IF($B25+D$23 <= LatestYear,E6/D6,""),""),"") -> 1.1974653 | E25: =IFERROR(IF(F6<>"",IF($B25+E$23 <= LatestYear,F6/E6,""),""),"") -> 1.0719934 | F25: =IFERROR(IF(G6<>"",IF($B25+F$23 <= LatestYear,G6/F6,""),""),"") -> 1.0329825 | G25: =IFERROR(IF(H6<>"",IF($B25+G$23 <= LatestYear,H6/G6,""),""),"") -> 1.0268332 | H25: =IFERROR(IF(I6<>"",IF($B25+H$23 <= LatestYear,I6/H6,""),""),"") -> 1.0099048 | I25: =IFERROR(IF(J6<>"",IF($B25+I$23 <= LatestYear,J6/I6,""),""),"") -> 1.0114954 | J25: =IFERROR(IF(K6<>"",IF($B25+J$23 <= LatestYear,K6/J6,""),""),"") -> 1.00775 | ... N25: =IFERROR(IF(O6<>"",IF($B25+N$23 <= LatestYear,O6/N6,""),""),"")
B26: 2011 | C26: =IFERROR(IF(D7<>"",IF($B26+C$23 <= LatestYear,D7/C7,""),""),"") -> 2.0622281 | D26: =IFERROR(IF(E7<>"",IF($B26+D$23 <= LatestYear,E7/D7,""),""),"") -> 1.1662536 | E26: =IFERROR(IF(F7<>"",IF($B26+E$23 <= LatestYear,F7/E7,""),""),"") -> 1.0664135 | F26: =IFERROR(IF(G7<>"",IF($B26+F$23 <= LatestYear,G7/F7,""),""),"") -> 1.0310642 | G26: =IFERROR(IF(H7<>"",IF($B26+G$23 <= LatestYear,H7/G7,""),""),"") -> 1.0126573 | H26: =IFERROR(IF(I7<>"",IF($B26+H$23 <= LatestYear,I7/H7,""),""),"") -> 1.0123563 | I26: =IFERROR(IF(J7<>"",IF($B26+I$23 <= LatestYear,J7/I7,""),""),"") -> 1.0110801 | J26: =IFERROR(IF(K7<>"",IF($B26+J$23 <= LatestYear,K7/J7,""),""),"") -> 1.0087342 | ... N26: =IFERROR(IF(O7<>"",IF($B26+N$23 <= LatestYear,O7/N7,""),""),"")
B27: 2012 | C27: =IFERROR(IF(D8<>"",IF($B27+C$23 <= LatestYear,D8/C8,""),""),"") -> 2.1009801 | D27: =IFERROR(IF(E8<>"",IF($B27+D$23 <= LatestYear,E8/D8,""),""),"") -> 1.1810063 | E27: =IFERROR(IF(F8<>"",IF($B27+E$23 <= LatestYear,F8/E8,""),""),"") -> 1.0557785 | F27: =IFERROR(IF(G8<>"",IF($B27+F$23 <= LatestYear,G8/F8,""),""),"") -> 1.0247025 | G27: =IFERROR(IF(H8<>"",IF($B27+G$23 <= LatestYear,H8/G8,""),""),"") -> 1.0182892 | H27: =IFERROR(IF(I8<>"",IF($B27+H$23 <= LatestYear,I8/H8,""),""),"") -> 1.019341 | I27: =IFERROR(IF(J8<>"",IF($B27+I$23 <= LatestYear,J8/I8,""),""),"") -> 1.0105166 | J27: =IFERROR(IF(K8<>"",IF($B27+J$23 <= LatestYear,K8/J8,""),""),"") -> 1.007668 | ... N27: =IFERROR(IF(O8<>"",IF($B27+N$23 <= LatestYear,O8/N8,""),""),"")
B28: 2013 | C28: =IFERROR(IF(D9<>"",IF($B28+C$23 <= LatestYear,D9/C9,""),""),"") -> 2.0311475 | D28: =IFERROR(IF(E9<>"",IF($B28+D$23 <= LatestYear,E9/D9,""),""),"") -> 1.171187 | E28: =IFERROR(IF(F9<>"",IF($B28+E$23 <= LatestYear,F9/E9,""),""),"") -> 1.0521992 | F28: =IFERROR(IF(G9<>"",IF($B28+F$23 <= LatestYear,G9/F9,""),""),"") -> 1.0230081 | G28: =IFERROR(IF(H9<>"",IF($B28+G$23 <= LatestYear,H9/G9,""),""),"") -> 1.0257282 | H28: =IFERROR(IF(I9<>"",IF($B28+H$23 <= LatestYear,I9/H9,""),""),"") -> 1.0111705 | I28: =IFERROR(IF(J9<>"",IF($B28+I$23 <= LatestYear,J9/I9,""),""),"") -> 1.0095962 | J28: =IFERROR(IF(K9<>"",IF($B28+J$23 <= LatestYear,K9/J9,""),""),"") | ... N28: =IFERROR(IF(O9<>"",IF($B28+N$23 <= LatestYear,O9/N9,""),""),"")
B29: 2014 | C29: =IFERROR(IF(D10<>"",IF($B29+C$23 <= LatestYear,D10/C10,""),""),"") -> 1.955185 | D29: =IFERROR(IF(E10<>"",IF($B29+D$23 <= LatestYear,E10/D10,""),""),"") -> 1.1814509 | E29: =IFERROR(IF(F10<>"",IF($B29+E$23 <= LatestYear,F10/E10,""),""),"") -> 1.0605556 | F29: =IFERROR(IF(G10<>"",IF($B29+F$23 <= LatestYear,G10/F10,""),""),"") -> 1.0319253 | G29: =IFERROR(IF(H10<>"",IF($B29+G$23 <= LatestYear,H10/G10,""),""),"") -> 1.0214374 | H29: =IFERROR(IF(I10<>"",IF($B29+H$23 <= LatestYear,I10/H10,""),""),"") -> 1.0174526 | I29: =IFERROR(IF(J10<>"",IF($B29+I$23 <= LatestYear,J10/I10,""),""),"") | J29: =IFERROR(IF(K10<>"",IF($B29+J$23 <= LatestYear,K10/J10,""),""),"") | ... N29: =IFERROR(IF(O10<>"",IF($B29+N$23 <= LatestYear,O10/N10,""),""),"")
B30: 2015 | C30: =IFERROR(IF(D11<>"",IF($B30+C$23 <= LatestYear,D11/C11,""),""),"") -> 2.007488 | D30: =IFERROR(IF(E11<>"",IF($B30+D$23 <= LatestYear,E11/D11,""),""),"") -> 1.196466 | E30: =IFERROR(IF(F11<>"",IF($B30+E$23 <= LatestYear,F11/E11,""),""),"") -> 1.0843007 | F30: =IFERROR(IF(G11<>"",IF($B30+F$23 <= LatestYear,G11/F11,""),""),"") -> 1.044494 | G30: =IFERROR(IF(H11<>"",IF($B30+G$23 <= LatestYear,H11/G11,""),""),"") -> 1.0245424 | H30: =IFERROR(IF(I11<>"",IF($B30+H$23 <= LatestYear,I11/H11,""),""),"") | I30: =IFERROR(IF(J11<>"",IF($B30+I$23 <= LatestYear,J11/I11,""),""),"") | J30: =IFERROR(IF(K11<>"",IF($B30+J$23 <= LatestYear,K11/J11,""),""),"") | ... N30: =IFERROR(IF(O11<>"",IF($B30+N$23 <= LatestYear,O11/N11,""),""),"")
B31: 2016 | C31: =IFERROR(IF(D12<>"",IF($B31+C$23 <= LatestYear,D12/C12,""),""),"") -> 2.0707734 | D31: =IFERROR(IF(E12<>"",IF($B31+D$23 <= LatestYear,E12/D12,""),""),"") -> 1.2172715 | E31: =IFERROR(IF(F12<>"",IF($B31+E$23 <= LatestYear,F12/E12,""),""),"") -> 1.070108 | F31: =IFERROR(IF(G12<>"",IF($B31+F$23 <= LatestYear,G12/F12,""),""),"") -> 1.0376572 | G31: =IFERROR(IF(H12<>"",IF($B31+G$23 <= LatestYear,H12/G12,""),""),"") | H31: =IFERROR(IF(I12<>"",IF($B31+H$23 <= LatestYear,I12/H12,""),""),"") | I31: =IFERROR(IF(J12<>"",IF($B31+I$23 <= LatestYear,J12/I12,""),""),"") | J31: =IFERROR(IF(K12<>"",IF($B31+J$23 <= LatestYear,K12/J12,""),""),"") | ... N31: =IFERROR(IF(O12<>"",IF($B31+N$23 <= LatestYear,O12/N12,""),""),"")
B32: 2017 | C32: =IFERROR(IF(D13<>"",IF($B32+C$23 <= LatestYear,D13/C13,""),""),"") -> 2.0219244 | D32: =IFERROR(IF(E13<>"",IF($B32+D$23 <= LatestYear,E13/D13,""),""),"") -> 1.1874506 | E32: =IFERROR(IF(F13<>"",IF($B32+E$23 <= LatestYear,F13/E13,""),""),"") -> 1.0761819 | F32: =IFERROR(IF(G13<>"",IF($B32+F$23 <= LatestYear,G13/F13,""),""),"") | G32: =IFERROR(IF(H13<>"",IF($B32+G$23 <= LatestYear,H13/G13,""),""),"") | H32: =IFERROR(IF(I13<>"",IF($B32+H$23 <= LatestYear,I13/H13,""),""),"") | I32: =IFERROR(IF(J13<>"",IF($B32+I$23 <= LatestYear,J13/I13,""),""),"") | J32: =IFERROR(IF(K13<>"",IF($B32+J$23 <= LatestYear,K13/J13,""),""),"") | ... N32: =IFERROR(IF(O13<>"",IF($B32+N$23 <= LatestYear,O13/N13,""),""),"")
B33: 2018 | C33: =IFERROR(IF(D14<>"",IF($B33+C$23 <= LatestYear,D14/C14,""),""),"") -> 1.9622667 | D33: =IFERROR(IF(E14<>"",IF($B33+D$23 <= LatestYear,E14/D14,""),""),"") -> 1.1802755 | E33: =IFERROR(IF(F14<>"",IF($B33+E$23 <= LatestYear,F14/E14,""),""),"") | F33: =IFERROR(IF(G14<>"",IF($B33+F$23 <= LatestYear,G14/F14,""),""),"") | G33: =IFERROR(IF(H14<>"",IF($B33+G$23 <= LatestYear,H14/G14,""),""),"") | H33: =IFERROR(IF(I14<>"",IF($B33+H$23 <= LatestYear,I14/H14,""),""),"") | I33: =IFERROR(IF(J14<>"",IF($B33+I$23 <= LatestYear,J14/I14,""),""),"") | J33: =IFERROR(IF(K14<>"",IF($B33+J$23 <= LatestYear,K14/J14,""),""),"") | ... N33: =IFERROR(IF(O14<>"",IF($B33+N$23 <= LatestYear,O14/N14,""),""),"")
B34: 2019 | C34: =IFERROR(IF(D15<>"",IF($B34+C$23 <= LatestYear,D15/C15,""),""),"") -> 1.9171317 | D34: =IFERROR(IF(E15<>"",IF($B34+D$23 <= LatestYear,E15/D15,""),""),"") | E34: =IFERROR(IF(F15<>"",IF($B34+E$23 <= LatestYear,F15/E15,""),""),"") | F34: =IFERROR(IF(G15<>"",IF($B34+F$23 <= LatestYear,G15/F15,""),""),"") | G34: =IFERROR(IF(H15<>"",IF($B34+G$23 <= LatestYear,H15/G15,""),""),"") | H34: =IFERROR(IF(I15<>"",IF($B34+H$23 <= LatestYear,I15/H15,""),""),"") | I34: =IFERROR(IF(J15<>"",IF($B34+I$23 <= LatestYear,J15/I15,""),""),"") | J34: =IFERROR(IF(K15<>"",IF($B34+J$23 <= LatestYear,K15/J15,""),""),"") | ... N34: =IFERROR(IF(O15<>"",IF($B34+N$23 <= LatestYear,O15/N15,""),""),"")
B35: 2020 | C35: =IFERROR(IF(D16<>"",IF($B35+C$23 <= LatestYear,D16/C16,""),""),"") | D35: =IFERROR(IF(E16<>"",IF($B35+D$23 <= LatestYear,E16/D16,""),""),"") | E35: =IFERROR(IF(F16<>"",IF($B35+E$23 <= LatestYear,F16/E16,""),""),"") | F35: =IFERROR(IF(G16<>"",IF($B35+F$23 <= LatestYear,G16/F16,""),""),"") | G35: =IFERROR(IF(H16<>"",IF($B35+G$23 <= LatestYear,H16/G16,""),""),"") | H35: =IFERROR(IF(I16<>"",IF($B35+H$23 <= LatestYear,I16/H16,""),""),"") | I35: =IFERROR(IF(J16<>"",IF($B35+I$23 <= LatestYear,J16/I16,""),""),"") | J35: =IFERROR(IF(K16<>"",IF($B35+J$23 <= LatestYear,K16/J16,""),""),"") | ... N35: =IFERROR(IF(O16<>"",IF($B35+N$23 <= LatestYear,O16/N16,""),""),"")
B37: Development factors | C37: 0->1 | D37: 1->2 | E37: 2->3 | F37: 3->4 | G37: 4->5 | H37: 5->6 | I37: 6->7 | J37: 7->8 | K37: 8->9 | L37: 9->10 | M37: 10->11
B38: Vol W Avg. | C38: {=IFERROR(MMULT(TRANSPOSE(OFFSET(C$23,1,0,COUNT(C$24:C$35))),OFFSET(C$4,1,0,COUNT(C$24:C$35)))/SUM(OFFSET(C$4,1,0,COUNT(C$24:C$35))),"")} -> 2.0171433 | D38: {=IFERROR(MMULT(TRANSPOSE(OFFSET(D$23,1,0,COUNT(D$24:D$35))),OFFSET(D$4,1,0,COUNT(D$24:D$35)))/SUM(OFFSET(D$4,1,0,COUNT(D$24:D$35))),"")} -> 1.1887196 | E38: {=IFERROR(MMULT(TRANSPOSE(OFFSET(E$23,1,0,COUNT(E$24:E$35))),OFFSET(E$4,1,0,COUNT(E$24:E$35)))/SUM(OFFSET(E$4,1,0,COUNT(E$24:E$35))),"")} -> 1.0679386 | F38: {=IFERROR(MMULT(TRANSPOSE(OFFSET(F$23,1,0,COUNT(F$24:F$35))),OFFSET(F$4,1,0,COUNT(F$24:F$35)))/SUM(OFFSET(F$4,1,0,COUNT(F$24:F$35))),"")} -> 1.033008 | G38: {=IFERROR(MMULT(TRANSPOSE(OFFSET(G$23,1,0,COUNT(G$24:G$35))),OFFSET(G$4,1,0,COUNT(G$24:G$35)))/SUM(OFFSET(G$4,1,0,COUNT(G$24:G$35))),"")} -> 1.0225797 | H38: {=IFERROR(MMULT(TRANSPOSE(OFFSET(H$23,1,0,COUNT(H$24:H$35))),OFFSET(H$4,1,0,COUNT(H$24:H$35)))/SUM(OFFSET(H$4,1,0,COUNT(H$24:H$35))),"")} -> 1.0145919 | I38: {=IFERROR(MMULT(TRANSPOSE(OFFSET(I$23,1,0,COUNT(I$24:I$35))),OFFSET(I$4,1,0,COUNT(I$24:I$35)))/SUM(OFFSET(I$4,1,0,COUNT(I$24:I$35))),"")} -> 1.011345 | J38: {=IFERROR(MMULT(TRANSPOSE(OFFSET(J$23,1,0,COUNT(J$24:J$35))),OFFSET(J$4,1,0,COUNT(J$24:J$35)))/SUM(OFFSET(J$4,1,0,COUNT(J$24:J$35))),"")} -> 1.00874 | ... M38: {=IFERROR(MMULT(TRANSPOSE(OFFSET(M$23,1,0,COUNT(M$24:M$35))),OFFSET(M$4,1,0,COUNT(M$24:M$35)))/SUM(OFFSET(M$4,1,0,COUNT(M$24:M$35))),"")} -> 1.0211086 | N38: 1
B39: CDF | C39: =PRODUCT(C$38:$N$38) -> 2.8896178 | D39: =PRODUCT(D$38:$N$38) -> 1.4325297 | E39: =PRODUCT(E$38:$N$38) -> 1.2051031 | F39: =PRODUCT(F$38:$N$38) -> 1.1284386 | G39: =PRODUCT(G$38:$N$38) -> 1.0923812 | H39: =PRODUCT(H$38:$N$38) -> 1.0682602 | I39: =PRODUCT(I$38:$N$38) -> 1.0528965 | J39: =PRODUCT(J$38:$N$38) -> 1.0410854 | ... M39: =PRODUCT(M$38:$N$38) -> 1.0211086 | N39: 1
E41: Weighted Squared Deviations
C42: DY
B43: AY | C43: 0 | D43: 1 | E43: 2 | F43: 3 | G43: 4 | H43: 5 | I43: 6 | J43: 7 | K43: 8 | L43: 9 | M43: 10 | N43: 11
B44: 2009 | C44: =IF($B44+C$43 < LatestYear,C5*(C24-C$38)^2,"") -> 3.5391093 | D44: =IF($B44+D$43 < LatestYear,D5*(D24-D$38)^2,"") -> 43.01251 | E44: =IF($B44+E$43 < LatestYear,E5*(E24-E$38)^2,"") -> 2.030212 | F44: =IF($B44+F$43 < LatestYear,F5*(F24-F$38)^2,"") -> 0.77294894 | G44: =IF($B44+G$43 < LatestYear,G5*(G24-G$38)^2,"") -> 4.5737961 | H44: =IF($B44+H$43 < LatestYear,H5*(H24-H$38)^2,"") -> 0.32158664 | I44: =IF($B44+I$43 < LatestYear,I5*(I24-I$38)^2,"") -> 1.185389 | J44: =IF($B44+J$43 < LatestYear,J5*(J24-J$38)^2,"") -> 0.56410131 | ... N44: =IF($B44+N$43 < LatestYear,N5*(N24-N$38)^2,"")
B45: 2010 | C45: =IF($B45+C$43 < LatestYear,C6*(C25-C$38)^2,"") -> 404.40887 | D45: =IF($B45+D$43 < LatestYear,D6*(D25-D$38)^2,"") -> 5.2063778 | E45: =IF($B45+E$43 < LatestYear,E6*(E25-E$38)^2,"") -> 1.3401688 | F45: =IF($B45+F$43 < LatestYear,F6*(F25-F$38)^2,"") -> 5.706727e-05 | G45: =IF($B45+G$43 < LatestYear,G6*(G25-G$38)^2,"") -> 1.6330363 | H45: =IF($B45+H$43 < LatestYear,H6*(H25-H$38)^2,"") -> 2.0361356 | I45: =IF($B45+I$43 < LatestYear,I6*(I25-I$38)^2,"") -> 0.0021162108 | J45: =IF($B45+J$43 < LatestYear,J6*(J25-J$38)^2,"") -> 0.092803751 | ... N45: =IF($B45+N$43 < LatestYear,N6*(N25-N$38)^2,"")
B46: 2011 | C46: =IF($B46+C$43 < LatestYear,C7*(C26-C$38)^2,"") -> 76.782375 | D46: =IF($B46+D$43 < LatestYear,D7*(D26-D$38)^2,"") -> 39.318047 | E46: =IF($B46+E$43 < LatestYear,E7*(E26-E$38)^2,"") -> 0.21131248 | F46: =IF($B46+F$43 < LatestYear,F7*(F26-F$38)^2,"") -> 0.36608058 | G46: =IF($B46+G$43 < LatestYear,G7*(G26-G$38)^2,"") -> 9.8350173 | H46: =IF($B46+H$43 < LatestYear,H7*(H26-H$38)^2,"") -> 0.50557406 | I46: =IF($B46+I$43 < LatestYear,I7*(I26-I$38)^2,"") -> 0.007185791 | J46: =IF($B46+J$43 < LatestYear,J7*(J26-J$38)^2,"") -> 3.5052603e-06 | ... N46: =IF($B46+N$43 < LatestYear,N7*(N26-N$38)^2,"")
B47: 2012 | C47: =IF($B47+C$43 < LatestYear,C8*(C27-C$38)^2,"") -> 284.07912 | D47: =IF($B47+D$43 < LatestYear,D8*(D27-D$38)^2,"") -> 5.0521767 | E47: =IF($B47+E$43 < LatestYear,E8*(E27-E$38)^2,"") -> 14.829313 | F47: =IF($B47+F$43 < LatestYear,F8*(F27-F$38)^2,"") -> 7.3039084 | G47: =IF($B47+G$43 < LatestYear,G8*(G27-G$38)^2,"") -> 1.9972128 | H47: =IF($B47+H$43 < LatestYear,H8*(H27-H$38)^2,"") -> 2.4917866 | I47: =IF($B47+I$43 < LatestYear,I8*(I27-I$38)^2,"") -> 0.07728299 | J47: =IF($B47+J$43 < LatestYear,J8*(J27-J$38)^2,"") -> 0.13077887 | ... N47: =IF($B47+N$43 < LatestYear,N8*(N27-N$38)^2,"")
...
