Workbook
Name NC: '[1]Calcolo PE di Mack'!$C$7
Name NR: '[1]Calcolo PE di Mack'!$C$6

Sheet MTPL
A1: Incremental Payments
B2: 0 | C2: =B2+1 -> 1 | D2: =C2+1 -> 2 | E2: =D2+1 -> 3 | F2: =E2+1 -> 4 | G2: =F2+1 -> 5 | H2: =G2+1 -> 6 | I2: =H2+1 -> 7 | J2: =I2+1 -> 8 | ... N2: =M2+1 -> 12
A3: 1993 | B3: 28446.238 | C3: 29251.193 | D3: 12463.984 | E3: 5144.0853 | F3: 2726.9478 | G3: 2359.3625 | H3: 1333.8561 | I3: 1238.43 | J3: 941.44048 | K3: 860.06389 | L3: 281.86968 | M3: 727.14207 | N3: 1068.0881
A4: =A3+1 -> 1994 | B4: 31963.048 | C4: 36106.295 | D4: 13441.333 | E4: 5868.2346 | F4: 2881.9723 | G4: 2421.9879 | H4: 918.00404 | I4: 1075.9783 | J4: 733.74103 | K4: 458.15607 | L4: 456.27065
A5: =A4+1 -> 1995 | B5: 37774.74 | C5: 40125.391 | D5: 12951.176 | E5: 6033.7555 | F5: 3009.6559 | G5: 1264.3963 | H5: 1249.9525 | I5: 1134.7061 | J5: 904.37117 | K5: 559.34005
A6: =A5+1 -> 1996 | B6: 40417.572 | C6: 44498.942 | D6: 15370.424 | E6: 5593.8535 | F6: 2615.5163 | G6: 1984.3118 | H6: 2136.8047 | I6: 1184.3554 | J6: 872.63333
A7: =A6+1 -> 1997 | B7: 44116.086 | C7: 45490.19 | D7: 15339.426 | E7: 5478.0768 | F7: 2540.6397 | G7: 2906.3686 | H7: 1294.338 | I7: 1124.3364
A8: =A7+1 -> 1998 | B8: 50294.26 | C8: 48040.322 | D8: 17842.902 | E8: 7035.1992 | F8: 3933.6061 | G8: 2725.6829 | H8: 2266.5999
A9: =A8+1 -> 1999 | B9: 49619.804 | C9: 49991.358 | D9: 19570.204 | E9: 10047.067 | F9: 5749.8901 | G9: 3312.6915
A10: =A9+1 -> 2000 | B10: 46409.721 | C10: 49694.295 | D10: 20880.667 | E10: 8201.5592 | F10: 4714.1682
A11: =A10+1 -> 2001 | B11: 48294.758 | C11: 49353.59 | D11: 18304.246 | E11: 8833.4878
A12: =A11+1 -> 2002 | B12: 52590.22 | C12: 50605.82 | D12: 18603.713
A13: =A12+1 -> 2003 | B13: 58599 | C13: 53743
A14: =A13+1 -> 2004 | B14: 60361.276
A18: Cumulative Payments
B19: 0 | C19: =B19+1 -> 1 | D19: =C19+1 -> 2 | E19: =D19+1 -> 3 | F19: =E19+1 -> 4 | G19: =F19+1 -> 5 | H19: =G19+1 -> 6 | I19: =H19+1 -> 7 | J19: =I19+1 -> 8 | ... N19: =M19+1 -> 12
A20: =A3 -> 1993 | B20: =B3 -> 28446.238 | C20: =B20+C3 -> 57697.432 | D20: =C20+D3 -> 70161.415 | E20: =D20+E3 -> 75305.501 | F20: =E20+F3 -> 78032.449 | G20: =F20+G3 -> 80391.811 | H20: =G20+H3 -> 81725.667 | I20: =H20+I3 -> 82964.097 | J20: =I20+J3 -> 83905.538 | ... N20: =M20+N3 -> 86842.701
A21: =A4 -> 1994 | B21: =B4 -> 31963.048 | C21: =B21+C4 -> 68069.343 | D21: =C21+D4 -> 81510.677 | E21: =D21+E4 -> 87378.911 | F21: =E21+F4 -> 90260.884 | G21: =F21+G4 -> 92682.871 | H21: =G21+H4 -> 93600.876 | I21: =H21+I4 -> 94676.854 | J21: =I21+J4 -> 95410.595 | ... L21: =K21+L4 -> 96325.022
A22: =A5 -> 1995 | B22: =B5 -> 37774.74 | C22: =B22+C5 -> 77900.131 | D22: =C22+D5 -> 90851.307 | E22: =D22+E5 -> 96885.063 | F22: =E22+F5 -> 99894.719 | G22: =F22+G5 -> 101159.11 | H22: =G22+H5 -> 102409.07 | I22: =H22+I5 -> 103543.77 | J22: =I22+J5 -> 104448.14 | K22: =J22+K5 -> 105007.48
A23: =A6 -> 1996 | B23: =B6 -> 40417.572 | C23: =B23+C6 -> 84916.514 | D23: =C23+D6 -> 100286.94 | E23: =D23+E6 -> 105880.79 | F23: =E23+F6 -> 108496.31 | G23: =F23+G6 -> 110480.62 | H23: =G23+H6 -> 112617.42 | I23: =H23+I6 -> 113801.78 | J23: =I23+J6 -> 114674.41
A24: =A7 -> 1997 | B24: =B7 -> 44116.086 | C24: =B24+C7 -> 89606.275 | D24: =C24+D7 -> 104945.7 | E24: =D24+E7 -> 110423.78 | F24: =E24+F7 -> 112964.42 | G24: =F24+G7 -> 115870.79 | H24: =G24+H7 -> 117165.12 | I24: =H24+I7 -> 118289.46
A25: =A8 -> 1998 | B25: =B8 -> 50294.26 | C25: =B25+C8 -> 98334.581 | D25: =C25+D8 -> 116177.48 | E25: =D25+E8 -> 123212.68 | F25: =E25+F8 -> 127146.29 | G25: =F25+G8 -> 129871.97 | H25: =G25+H8 -> 132138.57
A26: =A9 -> 1999 | B26: =B9 -> 49619.804 | C26: =B26+C9 -> 99611.162 | D26: =C26+D9 -> 119181.37 | E26: =D26+E9 -> 129228.43 | F26: =E26+F9 -> 134978.32 | G26: =F26+G9 -> 138291.01
A27: =A10 -> 2000 | B27: =B10 -> 46409.721 | C27: =B27+C10 -> 96104.016 | D27: =C27+D10 -> 116984.68 | E27: =D27+E10 -> 125186.24 | F27: =E27+F10 -> 129900.41
A28: =A11 -> 2001 | B28: =B11 -> 48294.758 | C28: =B28+C11 -> 97648.347 | D28: =C28+D11 -> 115952.59 | E28: =D28+E11 -> 124786.08
A29: =A12 -> 2002 | B29: =B12 -> 52590.22 | C29: =B29+C12 -> 103196.04 | D29: =C29+D12 -> 121799.75
A30: =A13 -> 2003 | B30: =B13 -> 58599 | C30: =B30+C13 -> 112342
A31: =A14 -> 2004 | B31: =B14 -> 60361.276
A33: Individual Dev. Factors
B34: =B19 -> 0 | C34: =C19 -> 1 | D34: =D19 -> 2 | E34: =E19 -> 3 | F34: =F19 -> 4 | G34: =G19 -> 5 | H34: =H19 -> 6 | I34: =I19 -> 7 | ... M34: =M19 -> 11
A35: =A20 -> 1993 | B35: =C20/B20 -> 2.0282974 | C35: =D20/C20 -> 1.2160232 | D35: =E20/D20 -> 1.0733179 | E35: =F20/E20 -> 1.0362118 | F35: =G20/F20 -> 1.0302357 | G35: =H20/G20 -> 1.0165919 | H35: =I20/H20 -> 1.0151535 | I35: =J20/I20 -> 1.0113476 | ... M35: =N20/M20 -> 1.0124523
A36: =A21 -> 1994 | B36: =C21/B21 -> 2.1296262 | C36: =D21/C21 -> 1.1974653 | D36: =E21/D21 -> 1.0719934 | E36: =F21/E21 -> 1.0329825 | F36: =G21/F21 -> 1.0268332 | G36: =H21/G21 -> 1.0099048 | H36: =I21/H21 -> 1.0114954 | I36: =J21/I21 -> 1.00775 | ... K36: =L21/K21 -> 1.0047593
A37: =A22 -> 1995 | B37: =C22/B22 -> 2.0622281 | C37: =D22/C22 -> 1.1662536 | D37: =E22/D22 -> 1.0664135 | E37: =F22/E22 -> 1.0310642 | F37: =G22/F22 -> 1.0126573 | G37: =H22/G22 -> 1.0123563 | H37: =I22/H22 -> 1.0110801 | I37: =J22/I22 -> 1.0087342 | J37: =K22/J22 -> 1.0053552
A38: =A23 -> 1996 | B38: =C23/B23 -> 2.1009801 | C38: =D23/C23 -> 1.1810063 | D38: =E23/D23 -> 1.0557785 | E38: =F23/E23 -> 1.0247025 | F38: =G23/F23 -> 1.0182892 | G38: =H23/G23 -> 1.019341 | H38: =I23/H23 -> 1.0105166 | I38: =J23/I23 -> 1.007668
A39: =A24 -> 1997 | B39: =C24/B24 -> 2.0311475 | C39: =D24/C24 -> 1.171187 | D39: =E24/D24 -> 1.0521992 | E39: =F24/E24 -> 1.0230081 | F39: =G24/F24 -> 1.0257282 | G39: =H24/G24 -> 1.0111705 | H39: =I24/H24 -> 1.0095962
A40: =A25 -> 1998 | B40: =C25/B25 -> 1.955185 | C40: =D25/C25 -> 1.1814509 | D40: =E25/D25 -> 1.0605556 | E40: =F25/E25 -> 1.0319253 | F40: =G25/F25 -> 1.0214374 | G40: =H25/G25 -> 1.0174526
A41: =A26 -> 1999 | B41: =C26/B26 -> 2.007488 | C41: =D26/C26 -> 1.196466 | D41: =E26/D26 -> 1.0843007 | E41: =F26/E26 -> 1.044494 | F41: =G26/F26 -> 1.0245424
A42: =A27 -> 2000 | B42: =C27/B27 -> 2.0707734 | C42: =D27/C27 -> 1.2172715 | D42: =E27/D27 -> 1.070108 | E42: =F27/E27 -> 1.0376572
A43: =A28 -> 2001 | B43: =C28/B28 -> 2.0219244 | C43: =D28/C28 -> 1.1874506 | D43: =E28/D28 -> 1.0761819
A44: =A29 -> 2002 | B44: =C29/B29 -> 1.9622667 | C44: =D29/C29 -> 1.1802755
...

Sheet GTPL
A1: Incremental Payments
B2: 0 | C2: =B2+1 -> 1 | D2: =C2+1 -> 2 | E2: =D2+1 -> 3 | F2: =E2+1 -> 4 | G2: =F2+1 -> 5 | H2: =G2+1 -> 6 | I2: =H2+1 -> 7 | J2: =I2+1 -> 8 | ... N2: =M2+1 -> 12
A3: 1993 | B3: 975.6 | C3: 1508.4 | D3: 674.1 | E3: 415.8 | F3: 514.8 | G3: 903.6 | H3: 1026 | I3: 821.7 | J3: 434.043 | K3: 329.2884 | L3: 242.424 | M3: 368 | N3: 2929
A4: =A3+1 -> 1994 | B4: 1253.7 | C4: 2601.9 | D4: 743.4 | E4: 438.3 | F4: 1431.9 | G4: 1355.4 | H4: 907.2 | I4: 671.5746 | J4: 466.1316 | K4: 559.377 | L4: 238.3425
A5: =A4+1 -> 1995 | B5: 1776.6 | C5: 2457.9 | D5: 811.8 | E5: 763.2 | F5: 1009.8 | G5: 848.7 | H5: 1130.5719 | I5: 1874.7972 | J5: 636.0705 | K5: 1364.3991
A6: =A5+1 -> 1996 | B6: 1255.5 | C6: 1917 | D6: 1019.7 | E6: 551.7 | F6: 776.7 | G6: 1439.5149 | H6: 2977.5519 | I6: 1979.0793 | J6: 728.541
A7: =A6+1 -> 1997 | B7: 998.1 | C7: 1976.4 | D7: 956.7 | E7: 444.6 | F7: 598.9167 | G7: 793.386 | H7: 1109.6505 | I7: 1144.1925
A8: =A7+1 -> 1998 | B8: 991.8 | C8: 1650.6 | D8: 612 | E8: 379.233 | F8: 452.1717 | G8: 579.3021 | H8: 656.9928
A9: =A8+1 -> 1999 | B9: 1025.1 | C9: 2025.9 | D9: 544.6944 | E9: 304.4574 | F9: 357.9336 | G9: 1103.0742
A10: =A9+1 -> 2000 | B10: 1044.9 | C10: 1962.9 | D10: 641.2473 | E10: 436.1211 | F10: 901.9719
A11: =A10+1 -> 2001 | B11: 889.6689 | C11: 1906.2693 | D11: 3481.8732 | E11: 882.4356
A12: =A11+1 -> 2002 | B12: 640.3905 | C12: 1422.2457 | D12: 689.769
A13: =A12+1 -> 2003 | B13: 784.5489 | C13: 1662.6123
A14: =A13+1 -> 2004 | B14: 893.6325
A18: Cumulative Payments
B19: 0 | C19: =B19+1 -> 1 | D19: =C19+1 -> 2 | E19: =D19+1 -> 3 | F19: =E19+1 -> 4 | G19: =F19+1 -> 5 | H19: =G19+1 -> 6 | I19: =H19+1 -> 7 | J19: =I19+1 -> 8 | ... N19: =M19+1 -> 12
A20: =A3 -> 1993 | B20: =B3 -> 975.6 | C20: =B20+C3 -> 2484 | D20: =C20+D3 -> 3158.1 | E20: =D20+E3 -> 3573.9 | F20: =E20+F3 -> 4088.7 | G20: =F20+G3 -> 4992.3 | H20: =G20+H3 -> 6018.3 | I20: =H20+I3 -> 6840 | J20: =I20+J3 -> 7274.043 | ... N20: =M20+N3 -> 11142.755
A21: =A4 -> 1994 | B21: =B4 -> 1253.7 | C21: =B21+C4 -> 3855.6 | D21: =C21+D4 -> 4599 | E21: =D21+E4 -> 5037.3 | F21: =E21+F4 -> 6469.2 | G21: =F21+G4 -> 7824.6 | H21: =G21+H4 -> 8731.8 | I21: =H21+I4 -> 9403.3746 | J21: =I21+J4 -> 9869.5062 | ... L21: =K21+L4 -> 10667.226
A22: =A5 -> 1995 | B22: =B5 -> 1776.6 | C22: =B22+C5 -> 4234.5 | D22: =C22+D5 -> 5046.3 | E22: =D22+E5 -> 5809.5 | F22: =E22+F5 -> 6819.3 | G22: =F22+G5 -> 7668 | H22: =G22+H5 -> 8798.5719 | I22: =H22+I5 -> 10673.369 | J22: =I22+J5 -> 11309.44 | K22: =J22+K5 -> 12673.839
A23: =A6 -> 1996 | B23: =B6 -> 1255.5 | C23: =B23+C6 -> 3172.5 | D23: =C23+D6 -> 4192.2 | E23: =D23+E6 -> 4743.9 | F23: =E23+F6 -> 5520.6 | G23: =F23+G6 -> 6960.1149 | H23: =G23+H6 -> 9937.6668 | I23: =H23+I6 -> 11916.746 | J23: =I23+J6 -> 12645.287
A24: =A7 -> 1997 | B24: =B7 -> 998.1 | C24: =B24+C7 -> 2974.5 | D24: =C24+D7 -> 3931.2 | E24: =D24+E7 -> 4375.8 | F24: =E24+F7 -> 4974.7167 | G24: =F24+G7 -> 5768.1027 | H24: =G24+H7 -> 6877.7532 | I24: =H24+I7 -> 8021.9457
A25: =A8 -> 1998 | B25: =B8 -> 991.8 | C25: =B25+C8 -> 2642.4 | D25: =C25+D8 -> 3254.4 | E25: =D25+E8 -> 3633.633 | F25: =E25+F8 -> 4085.8047 | G25: =F25+G8 -> 4665.1068 | H25: =G25+H8 -> 5322.0996
A26: =A9 -> 1999 | B26: =B9 -> 1025.1 | C26: =B26+C9 -> 3051 | D26: =C26+D9 -> 3595.6944 | E26: =D26+E9 -> 3900.1518 | F26: =E26+F9 -> 4258.0854 | G26: =F26+G9 -> 5361.1596
A27: =A10 -> 2000 | B27: =B10 -> 1044.9 | C27: =B27+C10 -> 3007.8 | D27: =C27+D10 -> 3649.0473 | E27: =D27+E10 -> 4085.1684 | F27: =E27+F10 -> 4987.1403
A28: =A11 -> 2001 | B28: =B11 -> 889.6689 | C28: =B28+C11 -> 2795.9382 | D28: =C28+D11 -> 6277.8114 | E28: =D28+E11 -> 7160.247
A29: =A12 -> 2002 | B29: =B12 -> 640.3905 | C29: =B29+C12 -> 2062.6362 | D29: =C29+D12 -> 2752.4052
A30: =A13 -> 2003 | B30: =B13 -> 784.5489 | C30: =B30+C13 -> 2447.1612
A31: =A14 -> 2004 | B31: =B14 -> 893.6325
A33: Individual Dev. Factors
B34: =B19 -> 0 | C34: =C19 -> 1 | D34: =D19 -> 2 | E34: =E19 -> 3 | F34: =F19 -> 4 | G34: =G19 -> 5 | H34: =H19 -> 6 | I34: =I19 -> 7 | ... M34: =M19 -> 11
A35: =A20 -> 1993 | B35: =C20/B20 -> 2.5461255 | C35: =D20/C20 -> 1.2713768 | D35: =E20/D20 -> 1.1316614 | E35: =F20/E20 -> 1.1440443 | F35: =G20/F20 -> 1.2209993 | G35: =H20/G20 -> 1.2055165 | H35: =I20/H20 -> 1.1365336 | I35: =J20/I20 -> 1.0634566 | ... M35: =N20/M20 -> 1.3565969
A36: =A21 -> 1994 | B36: =C21/B21 -> 3.0753769 | C36: =D21/C21 -> 1.1928105 | D36: =E21/D21 -> 1.0953033 | E36: =F21/E21 -> 1.2842594 | F36: =G21/F21 -> 1.2095159 | G36: =H21/G21 -> 1.115942 | H36: =I21/H21 -> 1.0769114 | I36: =J21/I21 -> 1.0495707 | ... K36: =L21/K21 -> 1.0228541
A37: =A22 -> 1995 | B37: =C22/B22 -> 2.3834853 | C37: =D22/C22 -> 1.1917109 | D37: =E22/D22 -> 1.1512395 | E37: =F22/E22 -> 1.1738187 | F37: =G22/F22 -> 1.1244556 | G37: =H22/G22 -> 1.1474403 | H37: =I22/H22 -> 1.2130797 | I37: =J22/I22 -> 1.0595942 | J37: =K22/J22 -> 1.1206425
A38: =A23 -> 1996 | B38: =C23/B23 -> 2.5268817 | C38: =D23/C23 -> 1.3214184 | D38: =E23/D23 -> 1.1316015 | E38: =F23/E23 -> 1.163726 | F38: =G23/F23 -> 1.2607533 | G38: =H23/G23 -> 1.4278021 | H38: =I23/H23 -> 1.1991493 | I38: =J23/I23 -> 1.0611359
A39: =A24 -> 1997 | B39: =C24/B24 -> 2.9801623 | C39: =D24/C24 -> 1.3216339 | D39: =E24/D24 -> 1.1130952 | E39: =F24/E24 -> 1.1368702 | F39: =G24/F24 -> 1.1594837 | G39: =H24/G24 -> 1.192377 | H39: =I24/H24 -> 1.1663614
A40: =A25 -> 1998 | B40: =C25/B25 -> 2.6642468 | C40: =D25/C25 -> 1.2316076 | D40: =E25/D25 -> 1.1165293 | E40: =F25/E25 -> 1.1244407 | F40: =G25/F25 -> 1.1417841 | G40: =H25/G25 -> 1.1408312
A41: =A26 -> 1999 | B41: =C26/B26 -> 2.976295 | C41: =D26/C26 -> 1.1785298 | D41: =E26/D26 -> 1.0846728 | E41: =F26/E26 -> 1.0917743 | F41: =G26/F26 -> 1.259054
A42: =A27 -> 2000 | B42: =C27/B27 -> 2.878553 | C42: =D27/C27 -> 1.2131948 | D42: =E27/D27 -> 1.1195164 | E42: =F27/E27 -> 1.2207919
A43: =A28 -> 2001 | B43: =C28/B28 -> 3.1426727 | C43: =D28/C28 -> 2.2453327 | D43: =E28/D28 -> 1.1405642
A44: =A29 -> 2002 | B44: =C29/B29 -> 3.2209038 | C44: =D29/C29 -> 1.3344114
...

Sheet MOD
A1: Incremental Payments
B2: 0 | C2: =B2+1 -> 1 | D2: =C2+1 -> 2 | E2: =D2+1 -> 3 | F2: =E2+1 -> 4 | G2: =F2+1 -> 5 | H2: =G2+1 -> 6 | I2: =H2+1 -> 7 | J2: =I2+1 -> 8 | ... N2: =M2+1 -> 12
A3: 1993 | B3: 14364 | C3: 5755.2 | D3: 76.8 | E3: 3.2 | F3: 32 | G3: 9.6 | H3: 28 | I3: 12.8 | J3: 4 | K3: 16.8 | L3: 5.6 | M3: 4 | N3: 130
A4: =A3+1 -> 1994 | B4: 16551.2 | C4: 6512 | D4: 277.6 | E4: 108.8 | F4: 28 | G4: 40.8 | H4: 118.4 | I4: 51.2 | J4: 7.2 | K4: 7.2 | L4: 23.2
A5: =A4+1 -> 1995 | B5: 16100 | C5: 6676.8 | D5: 280.8 | E5: 115.2 | F5: 16.8 | G5: 40 | H5: 66.4 | I5: 31.2 | J5: 8 | K5: 24.8
A6: =A5+1 -> 1996 | B6: 15543.2 | C6: 6352 | D6: 144.8 | E6: 12 | F6: 20 | G6: 40 | H6: 5.6 | I6: 0.8 | J6: 3.2
A7: =A6+1 -> 1997 | B7: 15372 | C7: 7162.4 | D7: 401.6 | E7: 16.8 | F7: 16 | G7: 9.6 | H7: 40 | I7: 2.4
A8: =A7+1 -> 1998 | B8: 17580.8 | C8: 7196 | D8: 259.2 | E8: 149.6 | F8: 159.2 | G8: 14.4 | H8: 28
A9: =A8+1 -> 1999 | B9: 18640.8 | C9: 6702.4 | D9: 212 | E9: 120.8 | F9: 28 | G9: 59.2
A10: =A9+1 -> 2000 | B10: 21061.6 | C10: 7196 | D10: 499.2 | E10: 164 | F10: 75.2
A11: =A10+1 -> 2001 | B11: 25591.2 | C11: 8682.4 | D11: 302.4 | E11: 74.4
A12: =A11+1 -> 2002 | B12: 25920.8 | C12: 8685.6 | D12: 580.8
A13: =A12+1 -> 2003 | B13: 28349.6 | C13: 9142.4
A14: =A13+1 -> 2004 | B14: 41857.6
A18: Cumulative Payments
B19: 0 | C19: =B19+1 -> 1 | D19: =C19+1 -> 2 | E19: =D19+1 -> 3 | F19: =E19+1 -> 4 | G19: =F19+1 -> 5 | H19: =G19+1 -> 6 | I19: =H19+1 -> 7 | J19: =I19+1 -> 8 | ... N19: =M19+1 -> 12
A20: =A3 -> 1993 | B20: =B3 -> 14364 | C20: =B20+C3 -> 20119.2 | D20: =C20+D3 -> 20196 | E20: =D20+E3 -> 20199.2 | F20: =E20+F3 -> 20231.2 | G20: =F20+G3 -> 20240.8 | H20: =G20+H3 -> 20268.8 | I20: =H20+I3 -> 20281.6 | J20: =I20+J3 -> 20285.6 | ... N20: =M20+N3 -> 20442
A21: =A4 -> 1994 | B21: =B4 -> 16551.2 | C21: =B21+C4 -> 23063.2 | D21: =C21+D4 -> 23340.8 | E21: =D21+E4 -> 23449.6 | F21: =E21+F4 -> 23477.6 | G21: =F21+G4 -> 23518.4 | H21: =G21+H4 -> 23636.8 | I21: =H21+I4 -> 23688 | J21: =I21+J4 -> 23695.2 | ... L21: =K21+L4 -> 23725.6
A22: =A5 -> 1995 | B22: =B5 -> 16100 | C22: =B22+C5 -> 22776.8 | D22: =C22+D5 -> 23057.6 | E22: =D22+E5 -> 23172.8 | F22: =E22+F5 -> 23189.6 | G22: =F22+G5 -> 23229.6 | H22: =G22+H5 -> 23296 | I22: =H22+I5 -> 23327.2 | J22: =I22+J5 -> 23335.2 | K22: =J22+K5 -> 23360
A23: =A6 -> 1996 | B23: =B6 -> 15543.2 | C23: =B23+C6 -> 21895.2 | D23: =C23+D6 -> 22040 | E23: =D23+E6 -> 22052 | F23: =E23+F6 -> 22072 | G23: =F23+G6 -> 22112 | H23: =G23+H6 -> 22117.6 | I23: =H23+I6 -> 22118.4 | J23: =I23+J6 -> 22121.6
A24: =A7 -> 1997 | B24: =B7 -> 15372 | C24: =B24+C7 -> 22534.4 | D24: =C24+D7 -> 22936 | E24: =D24+E7 -> 22952.8 | F24: =E24+F7 -> 22968.8 | G24: =F24+G7 -> 22978.4 | H24: =G24+H7 -> 23018.4 | I24: =H24+I7 -> 23020.8
A25: =A8 -> 1998 | B25: =B8 -> 17580.8 | C25: =B25+C8 -> 24776.8 | D25: =C25+D8 -> 25036 | E25: =D25+E8 -> 25185.6 | F25: =E25+F8 -> 25344.8 | G25: =F25+G8 -> 25359.2 | H25: =G25+H8 -> 25387.2
A26: =A9 -> 1999 | B26: =B9 -> 18640.8 | C26: =B26+C9 -> 25343.2 | D26: =C26+D9 -> 25555.2 | E26: =D26+E9 -> 25676 | F26: =E26+F9 -> 25704 | G26: =F26+G9 -> 25763.2
A27: =A10 -> 2000 | B27: =B10 -> 21061.6 | C27: =B27+C10 -> 28257.6 | D27: =C27+D10 -> 28756.8 | E27: =D27+E10 -> 28920.8 | F27: =E27+F10 -> 28996
A28: =A11 -> 2001 | B28: =B11 -> 25591.2 | C28: =B28+C11 -> 34273.6 | D28: =C28+D11 -> 34576 | E28: =D28+E11 -> 34650.4
A29: =A12 -> 2002 | B29: =B12 -> 25920.8 | C29: =B29+C12 -> 34606.4 | D29: =C29+D12 -> 35187.2
A30: =A13 -> 2003 | B30: =B13 -> 28349.6 | C30: =B30+C13 -> 37492
A31: =A14 -> 2004 | B31: =B14 -> 41857.6
A33: Individual Dev. Factors
B34: =B19 -> 0 | C34: =C19 -> 1 | D34: =D19 -> 2 | E34: =E19 -> 3 | F34: =F19 -> 4 | G34: =G19 -> 5 | H34: =H19 -> 6 | I34: =I19 -> 7 | ... M34: =M19 -> 11
A35: =A20 -> 1993 | B35: =C20/B20 -> 1.4006683 | C35: =D20/C20 -> 1.0038172 | D35: =E20/D20 -> 1.0001584 | E35: =F20/E20 -> 1.0015842 | F35: =G20/F20 -> 1.0004745 | G35: =H20/G20 -> 1.0013833 | H35: =I20/H20 -> 1.0006315 | I35: =J20/I20 -> 1.0001972 | ... M35: =N20/M20 -> 1.0064002
A36: =A21 -> 1994 | B36: =C21/B21 -> 1.3934458 | C36: =D21/C21 -> 1.0120365 | D36: =E21/D21 -> 1.0046614 | E36: =F21/E21 -> 1.0011941 | F36: =G21/F21 -> 1.0017378 | G36: =H21/G21 -> 1.0050344 | H36: =I21/H21 -> 1.0021661 | I36: =J21/I21 -> 1.000304 | ... K36: =L21/K21 -> 1.0009788
A37: =A22 -> 1995 | B37: =C22/B22 -> 1.4147081 | C37: =D22/C22 -> 1.0123283 | D37: =E22/D22 -> 1.0049962 | E37: =F22/E22 -> 1.000725 | F37: =G22/F22 -> 1.0017249 | G37: =H22/G22 -> 1.0028584 | H37: =I22/H22 -> 1.0013393 | I37: =J22/I22 -> 1.0003429 | J37: =K22/J22 -> 1.0010628
A38: =A23 -> 1996 | B38: =C23/B23 -> 1.4086675 | C38: =D23/C23 -> 1.0066133 | D38: =E23/D23 -> 1.0005445 | E38: =F23/E23 -> 1.0009069 | F38: =G23/F23 -> 1.0018123 | G38: =H23/G23 -> 1.0002533 | H38: =I23/H23 -> 1.0000362 | I38: =J23/I23 -> 1.0001447
A39: =A24 -> 1997 | B39: =C24/B24 -> 1.4659381 | C39: =D24/C24 -> 1.0178216 | D39: =E24/D24 -> 1.0007325 | E39: =F24/E24 -> 1.0006971 | F39: =G24/F24 -> 1.000418 | G39: =H24/G24 -> 1.0017408 | H39: =I24/H24 -> 1.0001043
A40: =A25 -> 1998 | B40: =C25/B25 -> 1.4093102 | C40: =D25/C25 -> 1.0104614 | D40: =E25/D25 -> 1.0059754 | E40: =F25/E25 -> 1.0063211 | F40: =G25/F25 -> 1.0005682 | G40: =H25/G25 -> 1.0011041
A41: =A26 -> 1999 | B41: =C26/B26 -> 1.3595554 | C41: =D26/C26 -> 1.0083652 | D41: =E26/D26 -> 1.004727 | E41: =F26/E26 -> 1.0010905 | F41: =G26/F26 -> 1.0023031
A42: =A27 -> 2000 | B42: =C27/B27 -> 1.3416645 | C42: =D27/C27 -> 1.017666 | D42: =E27/D27 -> 1.005703 | E42: =F27/E27 -> 1.0026002
A43: =A28 -> 2001 | B43: =C28/B28 -> 1.3392729 | C43: =D28/C28 -> 1.0088231 | D43: =E28/D28 -> 1.0021518
A44: =A29 -> 2002 | B44: =C29/B29 -> 1.3350823 | C44: =D29/C29 -> 1.016783
...

Sheet MTPL_AMASES
A1: Incremental Payments
B2: 0 | C2: =B2+1 -> 1 | D2: =C2+1 -> 2 | E2: =D2+1 -> 3 | F2: =E2+1 -> 4 | G2: =F2+1 -> 5 | H2: =G2+1 -> 6 | I2: =H2+1 -> 7 | J2: =I2+1 -> 8 | ... N2: =M2+1 -> 12
A3: 1993 | B3: 193473.6 | C3: 172617.6 | D3: 87200.4 | E3: 45798 | F3: 29768.4 | G3: 19795.2 | H3: 19782 | I3: 17314.8 | J3: 13371.6 | K3: 12552 | L3: 8830.8 | M3: 8053 | N3: 19889
A4: =A3+1 -> 1994 | B4: 199854 | C4: 168966 | D4: 80542.8 | E4: 40656 | F4: 29053.2 | G4: 21121.2 | H4: 19964.4 | I4: 14248.8 | J4: 10719.6 | K4: 13683.6 | L4: 6008.4
A5: =A4+1 -> 1995 | B5: 225578.4 | C5: 186764.4 | D5: 93349.2 | E5: 47608.8 | F5: 30970.8 | G5: 26290.8 | H5: 17620.8 | I5: 18410.4 | J5: 14661.6 | K5: 7591.2
A6: =A5+1 -> 1996 | B6: 256398 | C6: 236678.4 | D6: 105615.6 | E6: 51171.6 | F6: 37338 | G6: 24085.2 | H6: 20754 | I6: 12081.6 | J6: 14137.2
A7: =A6+1 -> 1997 | B7: 282956.4 | C7: 263196 | D7: 120382.8 | E7: 63688.8 | F7: 37220.4 | G7: 29239.2 | H7: 23120.4 | I7: 15508.8
A8: =A7+1 -> 1998 | B8: 292428 | C8: 284401.2 | D8: 141399.6 | E8: 56390.4 | F8: 40195.2 | G8: 27955.2 | H8: 29986.8
A9: =A8+1 -> 1999 | B9: 312350.4 | C9: 285506.4 | D9: 131686.8 | E9: 75252 | F9: 46549.2 | G9: 38731.2
A10: =A9+1 -> 2000 | B10: 327673.2 | C10: 307992 | D10: 161516.4 | E10: 77965.2 | F10: 52695.6
A11: =A10+1 -> 2001 | B11: 339898.8 | C11: 326280 | D11: 185911.2 | E11: 101272.8
A12: =A11+1 -> 2002 | B12: 371275.2 | C12: 385846.8 | D12: 193005.6
A13: =A12+1 -> 2003 | B13: 388024.8 | C13: 390736.8
A14: =A13+1 -> 2004 | B14: 398685.6
A18: Cumulative Payments
B19: 0 | C19: =B19+1 -> 1 | D19: =C19+1 -> 2 | E19: =D19+1 -> 3 | F19: =E19+1 -> 4 | G19: =F19+1 -> 5 | H19: =G19+1 -> 6 | I19: =H19+1 -> 7 | J19: =I19+1 -> 8 | ... N19: =M19+1 -> 12
A20: =A3 -> 1993 | B20: =B3 -> 193473.6 | C20: =B20+C3 -> 366091.2 | D20: =C20+D3 -> 453291.6 | E20: =D20+E3 -> 499089.6 | F20: =E20+F3 -> 528858 | G20: =F20+G3 -> 548653.2 | H20: =G20+H3 -> 568435.2 | I20: =H20+I3 -> 585750 | J20: =I20+J3 -> 599121.6 | ... N20: =M20+N3 -> 648446.4
A21: =A4 -> 1994 | B21: =B4 -> 199854 | C21: =B21+C4 -> 368820 | D21: =C21+D4 -> 449362.8 | E21: =D21+E4 -> 490018.8 | F21: =E21+F4 -> 519072 | G21: =F21+G4 -> 540193.2 | H21: =G21+H4 -> 560157.6 | I21: =H21+I4 -> 574406.4 | J21: =I21+J4 -> 585126 | ... L21: =K21+L4 -> 604818
A22: =A5 -> 1995 | B22: =B5 -> 225578.4 | C22: =B22+C5 -> 412342.8 | D22: =C22+D5 -> 505692 | E22: =D22+E5 -> 553300.8 | F22: =E22+F5 -> 584271.6 | G22: =F22+G5 -> 610562.4 | H22: =G22+H5 -> 628183.2 | I22: =H22+I5 -> 646593.6 | J22: =I22+J5 -> 661255.2 | K22: =J22+K5 -> 668846.4
A23: =A6 -> 1996 | B23: =B6 -> 256398 | C23: =B23+C6 -> 493076.4 | D23: =C23+D6 -> 598692 | E23: =D23+E6 -> 649863.6 | F23: =E23+F6 -> 687201.6 | G23: =F23+G6 -> 711286.8 | H23: =G23+H6 -> 732040.8 | I23: =H23+I6 -> 744122.4 | J23: =I23+J6 -> 758259.6
A24: =A7 -> 1997 | B24: =B7 -> 282956.4 | C24: =B24+C7 -> 546152.4 | D24: =C24+D7 -> 666535.2 | E24: =D24+E7 -> 730224 | F24: =E24+F7 -> 767444.4 | G24: =F24+G7 -> 796683.6 | H24: =G24+H7 -> 819804 | I24: =H24+I7 -> 835312.8
A25: =A8 -> 1998 | B25: =B8 -> 292428 | C25: =B25+C8 -> 576829.2 | D25: =C25+D8 -> 718228.8 | E25: =D25+E8 -> 774619.2 | F25: =E25+F8 -> 814814.4 | G25: =F25+G8 -> 842769.6 | H25: =G25+H8 -> 872756.4
A26: =A9 -> 1999 | B26: =B9 -> 312350.4 | C26: =B26+C9 -> 597856.8 | D26: =C26+D9 -> 729543.6 | E26: =D26+E9 -> 804795.6 | F26: =E26+F9 -> 851344.8 | G26: =F26+G9 -> 890076
A27: =A10 -> 2000 | B27: =B10 -> 327673.2 | C27: =B27+C10 -> 635665.2 | D27: =C27+D10 -> 797181.6 | E27: =D27+E10 -> 875146.8 | F27: =E27+F10 -> 927842.4
A28: =A11 -> 2001 | B28: =B11 -> 339898.8 | C28: =B28+C11 -> 666178.8 | D28: =C28+D11 -> 852090 | E28: =D28+E11 -> 953362.8
A29: =A12 -> 2002 | B29: =B12 -> 371275.2 | C29: =B29+C12 -> 757122 | D29: =C29+D12 -> 950127.6
A30: =A13 -> 2003 | B30: =B13 -> 388024.8 | C30: =B30+C13 -> 778761.6
A31: =A14 -> 2004 | B31: =B14 -> 398685.6
A33: Individual Dev. Factors
B34: =B19 -> 0 | C34: =C19 -> 1 | D34: =D19 -> 2 | E34: =E19 -> 3 | F34: =F19 -> 4 | G34: =G19 -> 5 | H34: =H19 -> 6 | I34: =I19 -> 7 | ... M34: =M19 -> 11
A35: =A20 -> 1993 | B35: =C20/B20 -> 1.8922023 | C35: =D20/C20 -> 1.2381931 | D35: =E20/D20 -> 1.1010343 | E35: =F20/E20 -> 1.0596454 | F35: =G20/F20 -> 1.0374301 | G35: =H20/G20 -> 1.0360556 | H35: =I20/H20 -> 1.0304605 | I35: =J20/I20 -> 1.0228282 | ... M35: =N20/M20 -> 1.0316423
A36: =A21 -> 1994 | B36: =C21/B21 -> 1.8454472 | C36: =D21/C21 -> 1.2183797 | D36: =E21/D21 -> 1.0904748 | E36: =F21/E21 -> 1.05929 | F36: =G21/F21 -> 1.0406903 | G36: =H21/G21 -> 1.0369579 | H36: =I21/H21 -> 1.0254371 | I36: =J21/I21 -> 1.018662 | ... K36: =L21/K21 -> 1.0100339
A37: =A22 -> 1995 | B37: =C22/B22 -> 1.8279357 | C37: =D22/C22 -> 1.2263874 | D37: =E22/D22 -> 1.0941458 | E37: =F22/E22 -> 1.0559746 | F37: =G22/F22 -> 1.0449976 | G37: =H22/G22 -> 1.0288599 | H37: =I22/H22 -> 1.0293074 | I37: =J22/I22 -> 1.0226751 | J37: =K22/J22 -> 1.01148
A38: =A23 -> 1996 | B38: =C23/B23 -> 1.9230899 | C38: =D23/C23 -> 1.2141972 | D38: =E23/D23 -> 1.0854723 | E38: =F23/E23 -> 1.0574551 | F38: =G23/F23 -> 1.0350482 | G38: =H23/G23 -> 1.0291781 | H38: =I23/H23 -> 1.016504 | I38: =J23/I23 -> 1.0189985
A39: =A24 -> 1997 | B39: =C24/B24 -> 1.9301645 | C39: =D24/C24 -> 1.2204198 | D39: =E24/D24 -> 1.095552 | E39: =F24/E24 -> 1.0509712 | F39: =G24/F24 -> 1.0380994 | G39: =H24/G24 -> 1.0290208 | H39: =I24/H24 -> 1.0189177
A40: =A25 -> 1998 | B40: =C25/B25 -> 1.9725512 | C40: =D25/C25 -> 1.2451325 | D40: =E25/D25 -> 1.0785131 | E40: =F25/E25 -> 1.0518903 | F40: =G25/F25 -> 1.0343087 | G40: =H25/G25 -> 1.0355813
A41: =A26 -> 1999 | B41: =C26/B26 -> 1.9140581 | C41: =D26/C26 -> 1.2202648 | D41: =E26/D26 -> 1.1031494 | E41: =F26/E26 -> 1.0578398 | F41: =G26/F26 -> 1.0454941
A42: =A27 -> 2000 | B42: =C27/B27 -> 1.9399365 | C42: =D27/C27 -> 1.2540904 | D42: =E27/D27 -> 1.0978011 | E42: =F27/E27 -> 1.0602134
A43: =A28 -> 2001 | B43: =C28/B28 -> 1.9599328 | C43: =D28/C28 -> 1.279071 | D43: =E28/D28 -> 1.1188522
A44: =A29 -> 2002 | B44: =C29/B29 -> 2.0392474 | C44: =D29/C29 -> 1.2549201
...

Sheet GTPL_AMASES
A1: Incremental Payments
B2: 0 | C2: =B2+1 -> 1 | D2: =C2+1 -> 2 | E2: =D2+1 -> 3 | F2: =E2+1 -> 4 | G2: =F2+1 -> 5 | H2: =G2+1 -> 6 | I2: =H2+1 -> 7 | J2: =I2+1 -> 8 | ... N2: =M2+1 -> 12
A3: 1993 | B3: 13860.9 | C3: 22302.9 | D3: 14024.7 | E3: 9468.9 | F3: 8626.5 | G3: 10122.3 | H3: 9176.4 | I3: 7662.6 | J3: 7908.3 | K3: 6051.6 | L3: 5091.3 | M3: 3147 | N3: 16601
A4: =A3+1 -> 1994 | B4: 15602.4 | C4: 20247.3 | D4: 14734.8 | E4: 10854.9 | F4: 10320.3 | G4: 14836.5 | H4: 9461.7 | I4: 6842.7 | J4: 6028.2 | K4: 6087.6 | L4: 4357.8
A5: =A4+1 -> 1995 | B5: 18115.2 | C5: 25441.2 | D5: 15099.3 | E5: 13132.8 | F5: 12671.1 | G5: 10298.7 | H5: 11775.6 | I5: 7467.3 | J5: 4901.4 | K5: 6233.4
A6: =A5+1 -> 1996 | B6: 16987.5 | C6: 26185.5 | D6: 20205 | E6: 20398.5 | F6: 13755.6 | G6: 12483 | H6: 12410.1 | I6: 11217.6 | J6: 7269.3
A7: =A6+1 -> 1997 | B7: 18165.6 | C7: 32736.6 | D7: 24607.8 | E7: 17171.1 | F7: 15912.9 | G7: 13782.6 | H7: 11466.9 | I7: 11492.1
A8: =A7+1 -> 1998 | B8: 16601.4 | C8: 31349.7 | D8: 21313.8 | E8: 17271.9 | F8: 14651.1 | G8: 10314 | H8: 12011.4
A9: =A8+1 -> 1999 | B9: 16861.5 | C9: 30627.9 | D9: 34887.6 | E9: 16065.9 | F9: 10702.8 | G9: 21147.3
A10: =A9+1 -> 2000 | B10: 16088.4 | C10: 28623.6 | D10: 19633.5 | E10: 15401.7 | F10: 10086.3
A11: =A10+1 -> 2001 | B11: 15764.4 | C11: 22721.4 | D11: 14960.7 | E11: 9999
A12: =A11+1 -> 2002 | B12: 16591.5 | C12: 28925.1 | D12: 17748
A13: =A12+1 -> 2003 | B13: 17941.5 | C13: 28771.2
A14: =A13+1 -> 2004 | B14: 17127.9
A18: Cumulative Payments
B19: 0 | C19: =B19+1 -> 1 | D19: =C19+1 -> 2 | E19: =D19+1 -> 3 | F19: =E19+1 -> 4 | G19: =F19+1 -> 5 | H19: =G19+1 -> 6 | I19: =H19+1 -> 7 | J19: =I19+1 -> 8 | ... N19: =M19+1 -> 12
A20: =A3 -> 1993 | B20: =B3 -> 13860.9 | C20: =B20+C3 -> 36163.8 | D20: =C20+D3 -> 50188.5 | E20: =D20+E3 -> 59657.4 | F20: =E20+F3 -> 68283.9 | G20: =F20+G3 -> 78406.2 | H20: =G20+H3 -> 87582.6 | I20: =H20+I3 -> 95245.2 | J20: =I20+J3 -> 103153.5 | ... N20: =M20+N3 -> 134044.4
A21: =A4 -> 1994 | B21: =B4 -> 15602.4 | C21: =B21+C4 -> 35849.7 | D21: =C21+D4 -> 50584.5 | E21: =D21+E4 -> 61439.4 | F21: =E21+F4 -> 71759.7 | G21: =F21+G4 -> 86596.2 | H21: =G21+H4 -> 96057.9 | I21: =H21+I4 -> 102900.6 | J21: =I21+J4 -> 108928.8 | ... L21: =K21+L4 -> 119374.2
A22: =A5 -> 1995 | B22: =B5 -> 18115.2 | C22: =B22+C5 -> 43556.4 | D22: =C22+D5 -> 58655.7 | E22: =D22+E5 -> 71788.5 | F22: =E22+F5 -> 84459.6 | G22: =F22+G5 -> 94758.3 | H22: =G22+H5 -> 106533.9 | I22: =H22+I5 -> 114001.2 | J22: =I22+J5 -> 118902.6 | K22: =J22+K5 -> 125136
A23: =A6 -> 1996 | B23: =B6 -> 16987.5 | C23: =B23+C6 -> 43173 | D23: =C23+D6 -> 63378 | E23: =D23+E6 -> 83776.5 | F23: =E23+F6 -> 97532.1 | G23: =F23+G6 -> 110015.1 | H23: =G23+H6 -> 122425.2 | I23: =H23+I6 -> 133642.8 | J23: =I23+J6 -> 140912.1
A24: =A7 -> 1997 | B24: =B7 -> 18165.6 | C24: =B24+C7 -> 50902.2 | D24: =C24+D7 -> 75510 | E24: =D24+E7 -> 92681.1 | F24: =E24+F7 -> 108594 | G24: =F24+G7 -> 122376.6 | H24: =G24+H7 -> 133843.5 | I24: =H24+I7 -> 145335.6
A25: =A8 -> 1998 | B25: =B8 -> 16601.4 | C25: =B25+C8 -> 47951.1 | D25: =C25+D8 -> 69264.9 | E25: =D25+E8 -> 86536.8 | F25: =E25+F8 -> 101187.9 | G25: =F25+G8 -> 111501.9 | H25: =G25+H8 -> 123513.3
A26: =A9 -> 1999 | B26: =B9 -> 16861.5 | C26: =B26+C9 -> 47489.4 | D26: =C26+D9 -> 82377 | E26: =D26+E9 -> 98442.9 | F26: =E26+F9 -> 109145.7 | G26: =F26+G9 -> 130293
A27: =A10 -> 2000 | B27: =B10 -> 16088.4 | C27: =B27+C10 -> 44712 | D27: =C27+D10 -> 64345.5 | E27: =D27+E10 -> 79747.2 | F27: =E27+F10 -> 89833.5
A28: =A11 -> 2001 | B28: =B11 -> 15764.4 | C28: =B28+C11 -> 38485.8 | D28: =C28+D11 -> 53446.5 | E28: =D28+E11 -> 63445.5
A29: =A12 -> 2002 | B29: =B12 -> 16591.5 | C29: =B29+C12 -> 45516.6 | D29: =C29+D12 -> 63264.6
A30: =A13 -> 2003 | B30: =B13 -> 17941.5 | C30: =B30+C13 -> 46712.7
A31: =A14 -> 2004 | B31: =B14 -> 17127.9
A33: Individual Dev. Factors
B34: =B19 -> 0 | C34: =C19 -> 1 | D34: =D19 -> 2 | E34: =E19 -> 3 | F34: =F19 -> 4 | G34: =G19 -> 5 | H34: =H19 -> 6 | I34: =I19 -> 7 | ... M34: =M19 -> 11
A35: =A20 -> 1993 | B35: =C20/B20 -> 2.6090514 | C35: =D20/C20 -> 1.3878105 | D35: =E20/D20 -> 1.1886667 | E35: =F20/E20 -> 1.1446007 | F35: =G20/F20 -> 1.1482385 | G35: =H20/G20 -> 1.1170367 | H35: =I20/H20 -> 1.08749 | I35: =J20/I20 -> 1.083031 | ... M35: =N20/M20 -> 1.1413532
A36: =A21 -> 1994 | B36: =C21/B21 -> 2.2977042 | C36: =D21/C21 -> 1.411016 | D36: =E21/D21 -> 1.2145894 | E36: =F21/E21 -> 1.1679753 | F36: =G21/F21 -> 1.2067525 | G36: =H21/G21 -> 1.1092623 | H36: =I21/H21 -> 1.0712352 | I36: =J21/I21 -> 1.0585827 | ... K36: =L21/K21 -> 1.0378885
A37: =A22 -> 1995 | B37: =C22/B22 -> 2.4044118 | C37: =D22/C22 -> 1.3466609 | D37: =E22/D22 -> 1.2238964 | E37: =F22/E22 -> 1.176506 | F37: =G22/F22 -> 1.1219364 | G37: =H22/G22 -> 1.1242699 | H37: =I22/H22 -> 1.0700932 | I37: =J22/I22 -> 1.0429943 | J37: =K22/J22 -> 1.0524244
A38: =A23 -> 1996 | B38: =C23/B23 -> 2.541457 | C38: =D23/C23 -> 1.4680008 | D38: =E23/D23 -> 1.3218546 | E38: =F23/E23 -> 1.164194 | F38: =G23/F23 -> 1.1279886 | G38: =H23/G23 -> 1.1128036 | H38: =I23/H23 -> 1.0916282 | I38: =J23/I23 -> 1.0543935
A39: =A24 -> 1997 | B39: =C24/B24 -> 2.8021205 | C39: =D24/C24 -> 1.4834329 | D39: =E24/D24 -> 1.2274017 | E39: =F24/E24 -> 1.1716952 | F39: =G24/F24 -> 1.1269186 | G39: =H24/G24 -> 1.0937017 | H39: =I24/H24 -> 1.0858622
A40: =A25 -> 1998 | B40: =C25/B25 -> 2.8883769 | C40: =D25/C25 -> 1.4444903 | D40: =E25/D25 -> 1.2493601 | E40: =F25/E25 -> 1.1693049 | F40: =G25/F25 -> 1.1019292 | G40: =H25/G25 -> 1.1077237
A41: =A26 -> 1999 | B41: =C26/B26 -> 2.8164398 | C41: =D26/C26 -> 1.7346397 | D41: =E26/D26 -> 1.195029 | E41: =F26/E26 -> 1.1087209 | F41: =G26/F26 -> 1.1937529
A42: =A27 -> 2000 | B42: =C27/B27 -> 2.7791452 | C42: =D27/C27 -> 1.4391103 | D42: =E27/D27 -> 1.2393594 | E42: =F27/E27 -> 1.1264784
A43: =A28 -> 2001 | B43: =C28/B28 -> 2.4413108 | C43: =D28/C28 -> 1.388733 | D43: =E28/D28 -> 1.1870843
A44: =A29 -> 2002 | B44: =C29/B29 -> 2.7433686 | C44: =D29/C29 -> 1.3899237
...

Sheet MOD_AMASES
A1: Incremental Payments
B2: 0 | C2: =B2+1 -> 1 | D2: =C2+1 -> 2 | E2: =D2+1 -> 3 | F2: =E2+1 -> 4 | G2: =F2+1 -> 5 | H2: =G2+1 -> 6 | I2: =H2+1 -> 7 | J2: =I2+1 -> 8 | ... N2: =M2+1 -> 12
A3: 1993 | B3: 44496.9 | C3: 18158.4 | D3: 238.5 | E3: 16.2 | F3: 7.2 | G3: 6.3 | H3: 117 | I3: 25.2 | J3: 9 | K3: 9 | L3: 7.2 | M3: 7 | N3: 54
A4: =A3+1 -> 1994 | B4: 47530.8 | C4: 20244.6 | D4: 343.8 | E4: 9 | F4: 65.7 | G4: 9 | H4: 10.8 | I4: 11.7 | J4: 32.4 | K4: 68.4 | L4: 19.8
A5: =A4+1 -> 1995 | B5: 54502.2 | C5: 22690.8 | D5: 412.2 | E5: 173.7 | F5: 63.9 | G5: 168.3 | H5: 36.9 | I5: 48.6 | J5: 40.5 | K5: 17.1
A6: =A5+1 -> 1996 | B6: 52830.9 | C6: 21477.6 | D6: 622.8 | E6: 234 | F6: 138.6 | G6: 70.2 | H6: 9 | I6: 30.6 | J6: 52.2
A7: =A6+1 -> 1997 | B7: 46943.1 | C7: 24072.3 | D7: 1425.6 | E7: 291.6 | F7: 64.8 | G7: 52.2 | H7: 20.7 | I7: 33.3
A8: =A7+1 -> 1998 | B8: 55724.4 | C8: 24507.9 | D8: 1159.2 | E8: 1968.3 | F8: 145.8 | G8: 29.7 | H8: 113.4
A9: =A8+1 -> 1999 | B9: 63506.7 | C9: 27141.3 | D9: 1782.9 | E9: 148.5 | F9: 33.3 | G9: 36.9
A10: =A9+1 -> 2000 | B10: 68291.1 | C10: 29936.7 | D10: 995.4 | E10: 167.4 | F10: 100.8
A11: =A10+1 -> 2001 | B11: 73208.7 | C11: 28736.1 | D11: 1367.1 | E11: 342.9
A12: =A11+1 -> 2002 | B12: 74537.1 | C12: 31020.3 | D12: 1566.9
A13: =A12+1 -> 2003 | B13: 74209.5 | C13: 27705.6
A14: =A13+1 -> 2004 | B14: 72417.6
A18: Cumulative Payments
B19: 0 | C19: =B19+1 -> 1 | D19: =C19+1 -> 2 | E19: =D19+1 -> 3 | F19: =E19+1 -> 4 | G19: =F19+1 -> 5 | H19: =G19+1 -> 6 | I19: =H19+1 -> 7 | J19: =I19+1 -> 8 | ... N19: =M19+1 -> 12
A20: =A3 -> 1993 | B20: =B3 -> 44496.9 | C20: =B20+C3 -> 62655.3 | D20: =C20+D3 -> 62893.8 | E20: =D20+E3 -> 62910 | F20: =E20+F3 -> 62917.2 | G20: =F20+G3 -> 62923.5 | H20: =G20+H3 -> 63040.5 | I20: =H20+I3 -> 63065.7 | J20: =I20+J3 -> 63074.7 | ... N20: =M20+N3 -> 63151.9
A21: =A4 -> 1994 | B21: =B4 -> 47530.8 | C21: =B21+C4 -> 67775.4 | D21: =C21+D4 -> 68119.2 | E21: =D21+E4 -> 68128.2 | F21: =E21+F4 -> 68193.9 | G21: =F21+G4 -> 68202.9 | H21: =G21+H4 -> 68213.7 | I21: =H21+I4 -> 68225.4 | J21: =I21+J4 -> 68257.8 | ... L21: =K21+L4 -> 68346
A22: =A5 -> 1995 | B22: =B5 -> 54502.2 | C22: =B22+C5 -> 77193 | D22: =C22+D5 -> 77605.2 | E22: =D22+E5 -> 77778.9 | F22: =E22+F5 -> 77842.8 | G22: =F22+G5 -> 78011.1 | H22: =G22+H5 -> 78048 | I22: =H22+I5 -> 78096.6 | J22: =I22+J5 -> 78137.1 | K22: =J22+K5 -> 78154.2
A23: =A6 -> 1996 | B23: =B6 -> 52830.9 | C23: =B23+C6 -> 74308.5 | D23: =C23+D6 -> 74931.3 | E23: =D23+E6 -> 75165.3 | F23: =E23+F6 -> 75303.9 | G23: =F23+G6 -> 75374.1 | H23: =G23+H6 -> 75383.1 | I23: =H23+I6 -> 75413.7 | J23: =I23+J6 -> 75465.9
A24: =A7 -> 1997 | B24: =B7 -> 46943.1 | C24: =B24+C7 -> 71015.4 | D24: =C24+D7 -> 72441 | E24: =D24+E7 -> 72732.6 | F24: =E24+F7 -> 72797.4 | G24: =F24+G7 -> 72849.6 | H24: =G24+H7 -> 72870.3 | I24: =H24+I7 -> 72903.6
A25: =A8 -> 1998 | B25: =B8 -> 55724.4 | C25: =B25+C8 -> 80232.3 | D25: =C25+D8 -> 81391.5 | E25: =D25+E8 -> 83359.8 | F25: =E25+F8 -> 83505.6 | G25: =F25+G8 -> 83535.3 | H25: =G25+H8 -> 83648.7
A26: =A9 -> 1999 | B26: =B9 -> 63506.7 | C26: =B26+C9 -> 90648 | D26: =C26+D9 -> 92430.9 | E26: =D26+E9 -> 92579.4 | F26: =E26+F9 -> 92612.7 | G26: =F26+G9 -> 92649.6
A27: =A10 -> 2000 | B27: =B10 -> 68291.1 | C27: =B27+C10 -> 98227.8 | D27: =C27+D10 -> 99223.2 | E27: =D27+E10 -> 99390.6 | F27: =E27+F10 -> 99491.4
A28: =A11 -> 2001 | B28: =B11 -> 73208.7 | C28: =B28+C11 -> 101944.8 | D28: =C28+D11 -> 103311.9 | E28: =D28+E11 -> 103654.8
A29: =A12 -> 2002 | B29: =B12 -> 74537.1 | C29: =B29+C12 -> 105557.4 | D29: =C29+D12 -> 107124.3
A30: =A13 -> 2003 | B30: =B13 -> 74209.5 | C30: =B30+C13 -> 101915.1
A31: =A14 -> 2004 | B31: =B14 -> 72417.6
A33: Individual Dev. Factors
B34: =B19 -> 0 | C34: =C19 -> 1 | D34: =D19 -> 2 | E34: =E19 -> 3 | F34: =F19 -> 4 | G34: =G19 -> 5 | H34: =H19 -> 6 | I34: =I19 -> 7 | ... M34: =M19 -> 11
A35: =A20 -> 1993 | B35: =C20/B20 -> 1.4080824 | C35: =D20/C20 -> 1.0038065 | D35: =E20/D20 -> 1.0002576 | E35: =F20/E20 -> 1.0001144 | F35: =G20/F20 -> 1.0001001 | G35: =H20/G20 -> 1.0018594 | H35: =I20/H20 -> 1.0003997 | I35: =J20/I20 -> 1.0001427 | ... M35: =N20/M20 -> 1.0008558
A36: =A21 -> 1994 | B36: =C21/B21 -> 1.4259259 | C36: =D21/C21 -> 1.0050726 | D36: =E21/D21 -> 1.0001321 | E36: =F21/E21 -> 1.0009644 | F36: =G21/F21 -> 1.000132 | G36: =H21/G21 -> 1.0001584 | H36: =I21/H21 -> 1.0001715 | I36: =J21/I21 -> 1.0004749 | ... K36: =L21/K21 -> 1.0002898
A37: =A22 -> 1995 | B37: =C22/B22 -> 1.4163281 | C37: =D22/C22 -> 1.0053399 | D37: =E22/D22 -> 1.0022383 | E37: =F22/E22 -> 1.0008216 | F37: =G22/F22 -> 1.002162 | G37: =H22/G22 -> 1.000473 | H37: =I22/H22 -> 1.0006227 | I37: =J22/I22 -> 1.0005186 | J37: =K22/J22 -> 1.0002188
A38: =A23 -> 1996 | B38: =C23/B23 -> 1.4065348 | C38: =D23/C23 -> 1.0083813 | D38: =E23/D23 -> 1.0031229 | E38: =F23/E23 -> 1.0018439 | F38: =G23/F23 -> 1.0009322 | G38: =H23/G23 -> 1.0001194 | H38: =I23/H23 -> 1.0004059 | I38: =J23/I23 -> 1.0006922
A39: =A24 -> 1997 | B39: =C24/B24 -> 1.5127974 | C39: =D24/C24 -> 1.0200745 | D39: =E24/D24 -> 1.0040253 | E39: =F24/E24 -> 1.0008909 | F39: =G24/F24 -> 1.0007171 | G39: =H24/G24 -> 1.0002841 | H39: =I24/H24 -> 1.000457
A40: =A25 -> 1998 | B40: =C25/B25 -> 1.4398055 | C40: =D25/C25 -> 1.014448 | D40: =E25/D25 -> 1.0241831 | E40: =F25/E25 -> 1.001749 | F40: =G25/F25 -> 1.0003557 | G40: =H25/G25 -> 1.0013575
A41: =A26 -> 1999 | B41: =C26/B26 -> 1.427377 | C41: =D26/C26 -> 1.0196684 | D41: =E26/D26 -> 1.0016066 | E41: =F26/E26 -> 1.0003597 | F41: =G26/F26 -> 1.0003984
A42: =A27 -> 2000 | B42: =C27/B27 -> 1.438369 | C42: =D27/C27 -> 1.0101336 | D42: =E27/D27 -> 1.0016871 | E42: =F27/E27 -> 1.0010142
A43: =A28 -> 2001 | B43: =C28/B28 -> 1.392523 | C43: =D28/C28 -> 1.0134102 | D43: =E28/D28 -> 1.0033191
A44: =A29 -> 2002 | B44: =C29/B29 -> 1.4161726 | C44: =D29/C29 -> 1.0148441
...

Sheet Cfr
B1: Dev. Factors PAID CHL - SIFA | P1: Dev. Factors PAID CHL - AMASES
B2: =MTPL!B34 -> 0 | C2: =MTPL!C34 -> 1 | D2: =MTPL!D34 -> 2 | E2: =MTPL!E34 -> 3 | F2: =MTPL!F34 -> 4 | G2: =MTPL!G34 -> 5 | H2: =MTPL!H34 -> 6 | I2: =MTPL!I34 -> 7 | ... M2: =MTPL!M34 -> 11 | P2: =MTPL!P34 -> 0 | Q2: =C2 -> 1 | R2: =D2 -> 2 | S2: =E2 -> 3 | T2: =F2 -> 4 | U2: =G2 -> 5 | V2: =H2 -> 6 | W2: =I2 -> 7 | X2: =J2 -> 8 | ... AA2: =M2 -> 11
A3: RCA | B3: =MTPL!B48 -> 2.0171433 | C3: =MTPL!C48 -> 1.1887196 | D3: =MTPL!D48 -> 1.0679386 | E3: =MTPL!E48 -> 1.033008 | F3: =MTPL!F48 -> 1.0225797 | G3: =MTPL!G48 -> 1.0145919 | H3: =MTPL!H48 -> 1.011345 | I3: =MTPL!I48 -> 1.00874 | ... M3: =MTPL!M48 -> 1.0124523 | O3: RCA | P3: =MTPL_AMASES!B48 -> 1.9432821 | Q3: =MTPL_AMASES!C48 -> 1.2399591 | R3: =MTPL_AMASES!D48 -> 1.0970093 | S3: =MTPL_AMASES!E48 -> 1.0564976 | T3: =MTPL_AMASES!F48 -> 1.0393894 | U3: =MTPL_AMASES!G48 -> 1.0324009 | V3: =MTPL_AMASES!H48 -> 1.0234431 | W3: =MTPL_AMASES!I48 -> 1.0207341 | ... AA3: =MTPL_AMASES!M48 -> 1.0316423
A4: RCG | B4: =GTPL!B48 -> 2.8126756 | C4: =GTPL!C48 -> 1.3360301 | D4: =GTPL!D48 -> 1.1224241 | E4: =GTPL!E48 -> 1.1719086 | F4: =GTPL!F48 -> 1.193917 | G4: =GTPL!G48 -> 1.2061334 | H4: =GTPL!H48 -> 1.1608198 | I4: =GTPL!I48 -> 1.0583204 | ... M4: =GTPL!M48 -> 1.3565969 | O4: RCG | P4: =GTPL_AMASES!B48 -> 2.6317883 | Q4: =GTPL_AMASES!C48 -> 1.4546224 | R4: =GTPL_AMASES!D48 -> 1.2285593 | S4: =GTPL_AMASES!E48 -> 1.1525488 | T4: =GTPL_AMASES!F48 -> 1.1450699 | U4: =GTPL_AMASES!G48 -> 1.1098346 | V4: =GTPL_AMASES!H48 -> 1.0817694 | W4: =GTPL_AMASES!I48 -> 1.0585639 | ... AA4: =GTPL_AMASES!M48 -> 1.1413532
A5: CVT | B5: =MOD!B48 -> 1.3722568 | C5: =MOD!C48 -> 1.0117805 | D5: =MOD!D48 -> 1.0033917 | E5: =MOD!E48 -> 1.0019582 | F5: =MOD!F48 -> 1.0013105 | G5: =MOD!G48 -> 1.0020838 | H5: =MOD!H48 -> 1.0008759 | I5: =MOD!I48 -> 1.0002505 | ... M5: =MOD!M48 -> 1.0064002 | O5: CVT | P5: =MOD_AMASES!B48 -> 1.4204017 | Q5: =MOD_AMASES!C48 -> 1.0119514 | R5: =MOD_AMASES!D48 -> 1.0045765 | S5: =MOD_AMASES!E48 -> 1.0009811 | T5: =MOD_AMASES!F48 -> 1.0006988 | U5: =MOD_AMASES!G48 -> 1.0006981 | V5: =MOD_AMASES!H48 -> 1.0004178 | W5: =MOD_AMASES!I48 -> 1.0004709 | ... AA5: =MOD_AMASES!M48 -> 1.0008558
B31: 1/CDF PAID CHL - SIFA | P31: 1/CDF PAID CHL - AMASES
B32: =B2 -> 0 | C32: =C2 -> 1 | D32: =D2 -> 2 | E32: =E2 -> 3 | F32: =F2 -> 4 | G32: =G2 -> 5 | H32: =H2 -> 6 | I32: =I2 -> 7 | ... M32: =M2 -> 11 | P32: =P2 -> 0 | Q32: =Q2 -> 1 | R32: =R2 -> 2 | S32: =S2 -> 3 | T32: =T2 -> 4 | U32: =U2 -> 5 | V32: =V2 -> 6 | W32: =W2 -> 7 | ... AA32: =AA2 -> 11
A33: RCA | B33: =1/MTPL!B52 -> 0.34606653 | C33: =1/MTPL!C52 -> 0.69806578 | D33: =1/MTPL!D52 -> 0.82980451 | E33: =1/MTPL!E52 -> 0.88618028 | F33: =1/MTPL!F52 -> 0.91543135 | G33: =1/MTPL!G52 -> 0.93610149 | H33: =1/MTPL!H52 -> 0.94976097 | I33: =1/MTPL!I52 -> 0.96053603 | ... M33: =1/MTPL!M52 -> 0.98770089 | O33: RCA | P33: =1/MTPL_AMASES!B52 -> 0.29652817 | Q33: =1/MTPL_AMASES!C52 -> 0.57623787 | R33: =1/MTPL_AMASES!D52 -> 0.71451136 | S33: =1/MTPL_AMASES!E52 -> 0.78382561 | T33: =1/MTPL_AMASES!F52 -> 0.82810987 | U33: =1/MTPL_AMASES!G52 -> 0.8607286 | V33: =1/MTPL_AMASES!H52 -> 0.88861697 | W33: =1/MTPL_AMASES!I52 -> 0.90944892 | ... AA33: =1/MTPL_AMASES!M52 -> 0.96932823
A34: RCG | B34: =1/GTPL!B52 -> 0.07267428 | C34: =1/GTPL!C52 -> 0.20440917 | D34: =1/GTPL!D52 -> 0.2730968 | E34: =1/GTPL!E52 -> 0.30653042 | F34: =1/GTPL!F52 -> 0.35922563 | G34: =1/GTPL!G52 -> 0.42888559 | H34: =1/GTPL!H52 -> 0.51729323 | I34: =1/GTPL!I52 -> 0.6004842 | ... M34: =1/GTPL!M52 -> 0.73713863 | O34: RCG | P34: =1/GTPL_AMASES!B52 -> 0.098264462 | Q34: =1/GTPL_AMASES!C52 -> 0.25861126 | R34: =1/GTPL_AMASES!D52 -> 0.37618174 | S34: =1/GTPL_AMASES!E52 -> 0.46216159 | T34: =1/GTPL_AMASES!F52 -> 0.53266379 | U34: =1/GTPL_AMASES!G52 -> 0.60993726 | V34: =1/GTPL_AMASES!H52 -> 0.67692944 | W34: =1/GTPL_AMASES!I52 -> 0.73228152 | ... AA34: =1/GTPL_AMASES!M52 -> 0.87615298
A35: CVT | B35: =1/MOD!B52 -> 0.70752417 | C35: =1/MOD!C52 -> 0.97090484 | D35: =1/MOD!D52 -> 0.98234257 | E35: =1/MOD!E52 -> 0.98567434 | F35: =1/MOD!F52 -> 0.98760444 | G35: =1/MOD!G52 -> 0.98889872 | H35: =1/MOD!H52 -> 0.99095943 | I35: =1/MOD!I52 -> 0.99182745 | ... M35: =1/MOD!M52 -> 0.99364054 | O35: CVT | P35: =1/MOD_AMASES!B52 -> 0.68916483 | Q35: =1/MOD_AMASES!C52 -> 0.97889088 | R35: =1/MOD_AMASES!D52 -> 0.99059003 | S35: =1/MOD_AMASES!E52 -> 0.99512347 | T35: =1/MOD_AMASES!F52 -> 0.99609979 | U35: =1/MOD_AMASES!G52 -> 0.9967959 | V35: =1/MOD_AMASES!H52 -> 0.99749178 | W35: =1/MOD_AMASES!I52 -> 0.99790857 | ... AA35: =1/MOD_AMASES!M52 -> 0.99914492
